Workbook
Name INDUSTRY_MAP: Assumptions!$S$5:$AB$40

Sheet Cover
B2: CREDIT MONITORING ARRANGEMENT (CMA) REPORT
B3: Projected Financials for Bank Term-Loan & Working-Capital Appraisal
B5: Name of the Unit | C5: =Assumptions!C5
B6: Constitution | C6: =Assumptions!C6
B7: Line of Activity | C7: =Assumptions!C7
B8: Term Loan applied for (₹) | C8: =Assumptions!C8
B9: Promoters' Capital (₹) | C9: =Assumptions!C9
B10: Projection horizon | C10: 5 years (60 months), monthly
B12: CONTENTS
B13: Assumptions | C13: All input variables — the only sheet you type into (blue cells)
B14: Revenue Build-Up | C14: Revenue build-up — volume x price for every line, plus segments
B15: Expenses | C15: 60-month operating expenses, variable and period costs
B16: P & L | C16: 60-month P&L: revenue by line, EBITDA -> EBIT -> PBT -> PAT
B17: Annual_Summary | C17: Consolidated 5-year figures feeding every CMA form
B18: Form_II_Operating | C18: Form II — Operating statement for credit appraisal
B19: Form_III_BalanceSheet | C19: Form III — Projected balance sheet
B20: Form_IV_CA_CL | C20: Form IV — Current assets & current liabilities
B21: Form_V_MPBF | C21: Form V — Maximum permissible bank finance (Tandon)
B22: WC & CC-OD Limit | C22: Working capital assessment and the term-loan / WC borrowing split
B23: Form_VI_FundFlow | C23: Form VI — Fund-flow statement
B24: Repayment | C24: Term-loan repayment schedule, annual and month by month
... B29: Dashboard | C29: Charts: revenue, EBITDA, PAT, DSCR

Sheet Assumptions
A1: ASSUMPTIONS — KEY INPUTS
A2: Enter values only in the blue/shaded cells. Every other sheet updates automatically.
B3: TOTAL COST OF PROJECT | C3: =C8+C9 | D3: ₹ = promoters' capital + term loan applied for
B4: A. COMPANY & LOAN PARTICULARS | S4: Industry | T4: CapLabel | U4: ProdUnitLabel | V4: Cost1Long | W4: Cost1Short | X4: Cost2Long | Y4: Cost2Short | Z4: Cost3Short | AA4: ProdSheetTitle | AB4: SalesSheetTitle
B5: Name of the Unit | I5: INDUSTRY / BUSINESS TYPE → | S5: Agriculture & Farming | T5: Installed Capacity (land / livestock / output) | U5: Production (units) | V5: Seeds & fertiliser cost per unit (Year 1) | W5: Seeds & fertiliser | X5: Irrigation & power cost per unit (Year 1) | Y5: Irrigation & power | Z5: Farm overheads | AA5: Production Plan | AB5: Sales Plan
B6: Constitution (Proprietor / Partnership / Pvt Ltd) | S6: Technology & Software | T6: Service Delivery Capacity (billable hours/licenses p.a.) | U6: Service delivery (units) | V6: Cloud hosting cost per unit (Year 1) | W6: Cloud hosting | X6: API services & software licence cost per unit (Year 1) | Y6: API services & licences | Z6: Engineering overheads | AA6: Service Delivery Plan | AB6: Revenue Plan
B7: Line of Activity / Product | S7: Retail & E-Commerce | T7: Annual Purchase Capacity (units for resale) | U7: Purchase (units) | V7: Inventory purchase cost per unit (Year 1) | W7: Inventory purchase | X7: Packaging & freight cost per unit (Year 1) | Y7: Packaging & freight | Z7: Store overheads | AA7: Purchase / Inventory Plan | AB7: Sales Plan
B8: Term Loan applied for | D8: ₹ | S8: Manufacturing | T8: Installed Capacity (state your own unit -- tonnes/kg/pieces/sq.ft p.a. -- matching what you specified) | U8: Production (units) | V8: Raw material cost per unit (Year 1) | W8: Raw materials | X8: Power & fuel cost per unit (Year 1) | Y8: Power & fuel | Z8: Factory overheads | AA8: Production Plan | AB8: Sales Plan
B9: Promoters' Capital / Equity brought in | D9: ₹ | S9: Tourism & Hospitality | T9: Room / Cover Capacity (room-nights or covers p.a.) | U9: Rooms sold / covers served (units) | V9: F&B & housekeeping cost per room-night (Year 1) | W9: F&B & housekeeping | X9: Power & fuel cost per room-night (Year 1) | Y9: Power & fuel | Z9: Property overheads | AA9: Operations Plan | AB9: Revenue Plan
B10: Interest rate on Term Loan | D10: % p.a. | S10: Renewable Energy | T10: Installed Generation Capacity (units of energy p.a.) | U10: Energy generated (units) | V10: O&M cost per unit generated (Year 1) | W10: O&M cost | X10: Grid charges & evacuation cost per unit (Year 1) | Y10: Grid charges | Z10: Plant overheads | AA10: Generation Plan | AB10: Revenue Plan
B11: Term Loan tenure (in MONTHS, e.g. 60 for 5 years) | D11: years | S11: Healthcare & Pharma | T11: Service / Production Capacity (patients or units p.a.) | U11: Patients served / units produced | V11: Medicines & medical consumables per unit (Year 1) | W11: Medicines & consumables | X11: Diagnostic equipment & power cost per unit (Year 1) | Y11: Diagnostic equipment | Z11: Facility overheads | AA11: Service Delivery Plan | AB11: Revenue Plan
B12: Moratorium / holiday period (in MONTHS) | D12: months | S12: Education & Training | T12: Service Capacity (student seats / batches p.a.) | U12: Students / batches served | V12: Faculty & courseware cost per student (Year 1) | W12: Faculty cost | X12: Campus infrastructure cost per student (Year 1) | Y12: Campus infrastructure | Z12: Institute overheads | AA12: Academic Operations Plan | AB12: Revenue Plan
B13: Interest rate on Working Capital | D13: % p.a. | S13: General Business | T13: Capacity (units / customers / hours p.a.) | U13: Output (units) | V13: Direct cost per unit (Year 1) | W13: Direct cost | X13: Other direct cost per unit (Year 1) | Y13: Other direct cost | Z13: Operating overheads | AA13: Operations Plan | AB13: Revenue Plan
B14: Income Tax rate | D14: % | S14: Construction & Real Estate | T14: Project Execution Capacity (sq.ft / units p.a.) | U14: Construction / units completed | V14: Construction material cost per unit (Year 1) | W14: Construction materials | X14: Site machinery & power cost per unit (Year 1) | Y14: Site machinery | Z14: Project overheads | AA14: Project Execution Plan | AB14: Revenue Plan
B15: B. SALES VOLUME | S15: Food & Beverage / Restaurant | T15: Seating / Covers Capacity (covers p.a.) | U15: Covers served (units) | V15: Food & beverage cost per cover (Year 1) | W15: Food cost | X15: Kitchen fuel & gas cost per cover (Year 1) | Y15: Kitchen fuel | Z15: Restaurant overheads | AA15: Operations Plan | AB15: Revenue Plan
B16: Trips / consignments (Year 1) | D16: units p.a. | S16: Transportation & Logistics | T16: Fleet / Route Capacity (trips or tonnage p.a.) | U16: Trips / tonnage handled (units) | V16: Fuel & running cost per trip (Year 1) | W16: Fuel | X16: Vehicle maintenance cost per trip (Year 1) | Y16: Vehicle maintenance | Z16: Fleet overheads | AA16: Fleet Operations Plan | AB16: Revenue Plan
B17: Sales Growth | C17: Yr 1 | D17: Yr 2 | E17: Yr 3 | F17: Yr 4 | G17: Yr 5 | S17: Textile & Garments | T17: Installed Capacity (garments/fabric units p.a.) | U17: Production (units) | V17: Yarn & fabric cost per unit (Year 1) | W17: Yarn & fabric | X17: Power & fuel cost per unit (Year 1) | Y17: Power & fuel | Z17: Factory overheads | AA17: Production Plan | AB17: Sales Plan
B18: → growth index Year 1…5 (Year 1 = 1.00) | D18: % | S18: Automobile / Auto Ancillary | T18: Installed Capacity (components/vehicles p.a.) | U18: Production (units) | V18: Component & raw material cost per unit (Year 1) | W18: Components & raw materials | X18: Power & fuel cost per unit (Year 1) | Y18: Power & fuel | Z18: Factory overheads | AA18: Production Plan | AB18: Sales Plan
B19: C. MONTHLY PHASING FACTOR (optional — blank = equal spread) | S19: Import / Export Trading | T19: Annual Trading Capacity (units for import/export) | U19: Trading volume (units) | V19: Purchase / import cost per unit (Year 1) | W19: Purchase & import cost | X19: Freight, customs & logistics cost per unit (Year 1) | Y19: Freight & customs | Z19: Trading overheads | AA19: Trading Plan | AB19: Revenue Plan
B20: Relative weight per month (M1…M12) | C20: M1 | D20: M2 | E20: M3 | F20: M4 | G20: M5 | H20: M6 | I20: M7 | J20: M8 | K20: M9 | L20: M10 | M20: M11 | N20: M12 | S20: Media & Entertainment | T20: Content / Production Capacity (units/hours p.a.) | U20: Content produced (units) | V20: Content production cost per unit (Year 1) | W20: Content production | X20: Equipment & studio hire cost per unit (Year 1) | Y20: Equipment & studio hire | Z20: Studio overheads | AA20: Operations Plan | AB20: Revenue Plan
B21: → weights (e.g. 1.0 each, or seasonal) | S21: Mining & Minerals | T21: Installed Extraction Capacity (tonnes p.a.) | U21: Extraction (units) | V21: Extraction & blasting cost per tonne (Year 1) | W21: Extraction & blasting | X21: Power & fuel cost per tonne (Year 1) | Y21: Power & fuel | Z21: Mine overheads | AA21: Extraction Plan | AB21: Sales Plan
B22: D. PRICE & MARGIN (Year-1 base, escalated yearly)
B23: Revenue per trip (Year 1) | D23: ₹/unit
B24: annual price / value growth | D24: %
B25: Gross margin on sales (%) → Operating cost of services = Sales × (1 − margin) | D25: ₹/unit
B26: (cost of sales is margin-based, not per-unit) | D26: %
B27: (not used in this industry) | D27: ₹/unit
B28: annual power cost escalation | D28: %
B29: Other cost per unit of activity (packaging / fulfilment) | D29: ₹/unit
B30: annual other-variable escalation | D30: %
B31: E. FIXED / PERIOD COSTS (per month, Year-1 base, escalated below)
B32: Direct wages & salaries / month (Year 1) | D32: ₹/month
B33: annual wages escalation | D33: %
B34: Operating / facility overheads / month (Year 1) | D34: ₹/month
B35: annual factory-OH escalation | D35: %
B36: Repairs & maintenance / month (Year 1) | D36: ₹/month
B37: annual R&M escalation | D37: %
B38: Administrative expenses / month (Year 1) | D38: ₹/month
B39: annual admin escalation | D39: %
B40: Selling & distribution | D40: % of sales
...

Sheet Revenue Build-Up
A1: REVENUE BUILD-UP — Trips / consignments revenue plus every ancillary revenue stream
A2: Volume × price for every revenue line, the total that feeds the P&L and every downstream form, and the split across target-market segments.
B3: YEAR 1 | O3: YEAR 2 | AB3: YEAR 3 | AO3: YEAR 4 | BB3: YEAR 5
A4: Particulars | B4: M1 | C4: M2 | D4: M3 | E4: M4 | F4: M5 | G4: M6 | H4: M7 | I4: M8 | J4: M9 | K4: M10 | L4: M11 | M4: M12 | N4: Yr 1 Total | O4: M1 | P4: M2 | Q4: M3 | R4: M4 | S4: M5 | T4: M6 | U4: M7 | V4: M8 | W4: M9 | X4: M10 | Y4: M11 | Z4: M12 | AA4: Yr 2 Total | AB4: M1 | AC4: M2 | AD4: M3 | AE4: M4 | AF4: M5 | AG4: M6 | AH4: M7 | AI4: M8 | AJ4: M9 | AK4: M10 | AL4: M11 | AM4: M12 | AN4: Yr 3 Total | AO4: M1 | AP4: M2 | AQ4: M3 | AR4: M4 | AS4: M5 | AT4: M6 | AU4: M7 | AV4: M8 | AW4: M9 | AX4: M10 | AY4: M11 | AZ4: M12 | BA4: Yr 4 Total | BB4: M1 | BC4: M2 | BD4: M3 | BE4: M4 | BF4: M5 | BG4: M6 | BH4: M7 | BI4: M8 | BJ4: M9 | BK4: M10 | BL4: M11 | BM4: M12 | BN4: Yr 5 Total
A5: Growth index (Yr 1 = 100%) | B5: =Assumptions!$C$18 | C5: =Assumptions!$C$18 | D5: =Assumptions!$C$18 | E5: =Assumptions!$C$18 | F5: =Assumptions!$C$18 | G5: =Assumptions!$C$18 | H5: =Assumptions!$C$18 | I5: =Assumptions!$C$18 | ... M5: =Assumptions!$C$18 | N5: =B5 | O5: =Assumptions!$D$18 | P5: =Assumptions!$D$18 | Q5: =Assumptions!$D$18 | R5: =Assumptions!$D$18 | S5: =Assumptions!$D$18 | T5: =Assumptions!$D$18 | U5: =Assumptions!$D$18 | V5: =Assumptions!$D$18 | ... Z5: =Assumptions!$D$18 | AA5: =O5 | AB5: =Assumptions!$E$18 | AC5: =Assumptions!$E$18 | AD5: =Assumptions!$E$18 | AE5: =Assumptions!$E$18 | AF5: =Assumptions!$E$18 | AG5: =Assumptions!$E$18 | AH5: =Assumptions!$E$18 | AI5: =Assumptions!$E$18 | ... AM5: =Assumptions!$E$18 | AN5: =AB5 | AO5: =Assumptions!$F$18 | AP5: =Assumptions!$F$18 | AQ5: =Assumptions!$F$18 | AR5: =Assumptions!$F$18 | AS5: =Assumptions!$F$18 | AT5: =Assumptions!$F$18 | AU5: =Assumptions!$F$18 | AV5: =Assumptions!$F$18 | ... AZ5: =Assumptions!$F$18 | BA5: =AO5 | BB5: =Assumptions!$G$18 | BC5: =Assumptions!$G$18 | BD5: =Assumptions!$G$18 | BE5: =Assumptions!$G$18 | BF5: =Assumptions!$G$18 | BG5: =Assumptions!$G$18 | BH5: =Assumptions!$G$18 | BI5: =Assumptions!$G$18 | ... BM5: =Assumptions!$G$18 | BN5: =BB5
A6: Trips / consignments (units) | B6: =(Assumptions!$C$16*Assumptions!$C$18/12)*IF(SUM(Assumptions!$C$21:$N$21)=0,1,12*Assumptions!C$21/SUM(Assumptions!$C$21:$N$21)) | C6: =(Assumptions!$C$16*Assumptions!$C$18/12)*IF(SUM(Assumptions!$C$21:$N$21)=0,1,12*Assumptions!D$21/SUM(Assumptions!$C$21:$N$21)) | D6: =(Assumptions!$C$16*Assumptions!$C$18/12)*IF(SUM(Assumptions!$C$21:$N$21)=0,1,12*Assumptions!E$21/SUM(Assumptions!$C$21:$N$21)) | E6: =(Assumptions!$C$16*Assumptions!$C$18/12)*IF(SUM(Assumptions!$C$21:$N$21)=0,1,12*Assumptions!F$21/SUM(Assumptions!$C$21:$N$21)) | F6: =(Assumptions!$C$16*Assumptions!$C$18/12)*IF(SUM(Assumptions!$C$21:$N$21)=0,1,12*Assumptions!G$21/SUM(Assumptions!$C$21:$N$21)) | G6: =(Assumptions!$C$16*Assumptions!$C$18/12)*IF(SUM(Assumptions!$C$21:$N$21)=0,1,12*Assumptions!H$21/SUM(Assumptions!$C$21:$N$21)) | H6: =(Assumptions!$C$16*Assumptions!$C$18/12)*IF(SUM(Assumptions!$C$21:$N$21)=0,1,12*Assumptions!I$21/SUM(Assumptions!$C$21:$N$21)) | I6: =(Assumptions!$C$16*Assumptions!$C$18/12)*IF(SUM(Assumptions!$C$21:$N$21)=0,1,12*Assumptions!J$21/SUM(Assumptions!$C$21:$N$21)) | ... M6: =(Assumptions!$C$16*Assumptions!$C$18/12)*IF(SUM(Assumptions!$C$21:$N$21)=0,1,12*Assumptions!N$21/SUM(Assumptions!$C$21:$N$21)) | N6: =SUM(B6:M6) | O6: =(Assumptions!$C$16*Assumptions!$D$18/12)*IF(SUM(Assumptions!$C$21:$N$21)=0,1,12*Assumptions!C$21/SUM(Assumptions!$C$21:$N$21)) | P6: =(Assumptions!$C$16*Assumptions!$D$18/12)*IF(SUM(Assumptions!$C$21:$N$21)=0,1,12*Assumptions!D$21/SUM(Assumptions!$C$21:$N$21)) | Q6: =(Assumptions!$C$16*Assumptions!$D$18/12)*IF(SUM(Assumptions!$C$21:$N$21)=0,1,12*Assumptions!E$21/SUM(Assumptions!$C$21:$N$21)) | R6: =(Assumptions!$C$16*Assumptions!$D$18/12)*IF(SUM(Assumptions!$C$21:$N$21)=0,1,12*Assumptions!F$21/SUM(Assumptions!$C$21:$N$21)) | S6: =(Assumptions!$C$16*Assumptions!$D$18/12)*IF(SUM(Assumptions!$C$21:$N$21)=0,1,12*Assumptions!G$21/SUM(Assumptions!$C$21:$N$21)) | T6: =(Assumptions!$C$16*Assumptions!$D$18/12)*IF(SUM(Assumptions!$C$21:$N$21)=0,1,12*Assumptions!H$21/SUM(Assumptions!$C$21:$N$21)) | U6: =(Assumptions!$C$16*Assumptions!$D$18/12)*IF(SUM(Assumptions!$C$21:$N$21)=0,1,12*Assumptions!I$21/SUM(Assumptions!$C$21:$N$21)) | V6: =(Assumptions!$C$16*Assumptions!$D$18/12)*IF(SUM(Assumptions!$C$21:$N$21)=0,1,12*Assumptions!J$21/SUM(Assumptions!$C$21:$N$21)) | ... Z6: =(Assumptions!$C$16*Assumptions!$D$18/12)*IF(SUM(Assumptions!$C$21:$N$21)=0,1,12*Assumptions!N$21/SUM(Assumptions!$C$21:$N$21)) | AA6: =SUM(O6:Z6) | AB6: =(Assumptions!$C$16*Assumptions!$E$18/12)*IF(SUM(Assumptions!$C$21:$N$21)=0,1,12*Assumptions!C$21/SUM(Assumptions!$C$21:$N$21)) | AC6: =(Assumptions!$C$16*Assumptions!$E$18/12)*IF(SUM(Assumptions!$C$21:$N$21)=0,1,12*Assumptions!D$21/SUM(Assumptions!$C$21:$N$21)) | AD6: =(Assumptions!$C$16*Assumptions!$E$18/12)*IF(SUM(Assumptions!$C$21:$N$21)=0,1,12*Assumptions!E$21/SUM(Assumptions!$C$21:$N$21)) | AE6: =(Assumptions!$C$16*Assumptions!$E$18/12)*IF(SUM(Assumptions!$C$21:$N$21)=0,1,12*Assumptions!F$21/SUM(Assumptions!$C$21:$N$21)) | AF6: =(Assumptions!$C$16*Assumptions!$E$18/12)*IF(SUM(Assumptions!$C$21:$N$21)=0,1,12*Assumptions!G$21/SUM(Assumptions!$C$21:$N$21)) | AG6: =(Assumptions!$C$16*Assumptions!$E$18/12)*IF(SUM(Assumptions!$C$21:$N$21)=0,1,12*Assumptions!H$21/SUM(Assumptions!$C$21:$N$21)) | AH6: =(Assumptions!$C$16*Assumptions!$E$18/12)*IF(SUM(Assumptions!$C$21:$N$21)=0,1,12*Assumptions!I$21/SUM(Assumptions!$C$21:$N$21)) | AI6: =(Assumptions!$C$16*Assumptions!$E$18/12)*IF(SUM(Assumptions!$C$21:$N$21)=0,1,12*Assumptions!J$21/SUM(Assumptions!$C$21:$N$21)) | ... AM6: =(Assumptions!$C$16*Assumptions!$E$18/12)*IF(SUM(Assumptions!$C$21:$N$21)=0,1,12*Assumptions!N$21/SUM(Assumptions!$C$21:$N$21)) | AN6: =SUM(AB6:AM6) | AO6: =(Assumptions!$C$16*Assumptions!$F$18/12)*IF(SUM(Assumptions!$C$21:$N$21)=0,1,12*Assumptions!C$21/SUM(Assumptions!$C$21:$N$21)) | AP6: =(Assumptions!$C$16*Assumptions!$F$18/12)*IF(SUM(Assumptions!$C$21:$N$21)=0,1,12*Assumptions!D$21/SUM(Assumptions!$C$21:$N$21)) | AQ6: =(Assumptions!$C$16*Assumptions!$F$18/12)*IF(SUM(Assumptions!$C$21:$N$21)=0,1,12*Assumptions!E$21/SUM(Assumptions!$C$21:$N$21)) | AR6: =(Assumptions!$C$16*Assumptions!$F$18/12)*IF(SUM(Assumptions!$C$21:$N$21)=0,1,12*Assumptions!F$21/SUM(Assumptions!$C$21:$N$21)) | AS6: =(Assumptions!$C$16*Assumptions!$F$18/12)*IF(SUM(Assumptions!$C$21:$N$21)=0,1,12*Assumptions!G$21/SUM(Assumptions!$C$21:$N$21)) | AT6: =(Assumptions!$C$16*Assumptions!$F$18/12)*IF(SUM(Assumptions!$C$21:$N$21)=0,1,12*Assumptions!H$21/SUM(Assumptions!$C$21:$N$21)) | AU6: =(Assumptions!$C$16*Assumptions!$F$18/12)*IF(SUM(Assumptions!$C$21:$N$21)=0,1,12*Assumptions!I$21/SUM(Assumptions!$C$21:$N$21)) | AV6: =(Assumptions!$C$16*Assumptions!$F$18/12)*IF(SUM(Assumptions!$C$21:$N$21)=0,1,12*Assumptions!J$21/SUM(Assumptions!$C$21:$N$21)) | ... AZ6: =(Assumptions!$C$16*Assumptions!$F$18/12)*IF(SUM(Assumptions!$C$21:$N$21)=0,1,12*Assumptions!N$21/SUM(Assumptions!$C$21:$N$21)) | BA6: =SUM(AO6:AZ6) | BB6: =(Assumptions!$C$16*Assumptions!$G$18/12)*IF(SUM(Assumptions!$C$21:$N$21)=0,1,12*Assumptions!C$21/SUM(Assumptions!$C$21:$N$21)) | BC6: =(Assumptions!$C$16*Assumptions!$G$18/12)*IF(SUM(Assumptions!$C$21:$N$21)=0,1,12*Assumptions!D$21/SUM(Assumptions!$C$21:$N$21)) | BD6: =(Assumptions!$C$16*Assumptions!$G$18/12)*IF(SUM(Assumptions!$C$21:$N$21)=0,1,12*Assumptions!E$21/SUM(Assumptions!$C$21:$N$21)) | BE6: =(Assumptions!$C$16*Assumptions!$G$18/12)*IF(SUM(Assumptions!$C$21:$N$21)=0,1,12*Assumptions!F$21/SUM(Assumptions!$C$21:$N$21)) | BF6: =(Assumptions!$C$16*Assumptions!$G$18/12)*IF(SUM(Assumptions!$C$21:$N$21)=0,1,12*Assumptions!G$21/SUM(Assumptions!$C$21:$N$21)) | BG6: =(Assumptions!$C$16*Assumptions!$G$18/12)*IF(SUM(Assumptions!$C$21:$N$21)=0,1,12*Assumptions!H$21/SUM(Assumptions!$C$21:$N$21)) | BH6: =(Assumptions!$C$16*Assumptions!$G$18/12)*IF(SUM(Assumptions!$C$21:$N$21)=0,1,12*Assumptions!I$21/SUM(Assumptions!$C$21:$N$21)) | BI6: =(Assumptions!$C$16*Assumptions!$G$18/12)*IF(SUM(Assumptions!$C$21:$N$21)=0,1,12*Assumptions!J$21/SUM(Assumptions!$C$21:$N$21)) | ... BM6: =(Assumptions!$C$16*Assumptions!$G$18/12)*IF(SUM(Assumptions!$C$21:$N$21)=0,1,12*Assumptions!N$21/SUM(Assumptions!$C$21:$N$21)) | BN6: =SUM(BB6:BM6)
A7: Revenue per trip (₹ / unit) | B7: =Assumptions!$C$23*(1+Assumptions!$C$24)^0 | C7: =Assumptions!$C$23*(1+Assumptions!$C$24)^0 | D7: =Assumptions!$C$23*(1+Assumptions!$C$24)^0 | E7: =Assumptions!$C$23*(1+Assumptions!$C$24)^0 | F7: =Assumptions!$C$23*(1+Assumptions!$C$24)^0 | G7: =Assumptions!$C$23*(1+Assumptions!$C$24)^0 | H7: =Assumptions!$C$23*(1+Assumptions!$C$24)^0 | I7: =Assumptions!$C$23*(1+Assumptions!$C$24)^0 | ... M7: =Assumptions!$C$23*(1+Assumptions!$C$24)^0 | N7: =B7 | O7: =Assumptions!$C$23*(1+Assumptions!$C$24)^1 | P7: =Assumptions!$C$23*(1+Assumptions!$C$24)^1 | Q7: =Assumptions!$C$23*(1+Assumptions!$C$24)^1 | R7: =Assumptions!$C$23*(1+Assumptions!$C$24)^1 | S7: =Assumptions!$C$23*(1+Assumptions!$C$24)^1 | T7: =Assumptions!$C$23*(1+Assumptions!$C$24)^1 | U7: =Assumptions!$C$23*(1+Assumptions!$C$24)^1 | V7: =Assumptions!$C$23*(1+Assumptions!$C$24)^1 | ... Z7: =Assumptions!$C$23*(1+Assumptions!$C$24)^1 | AA7: =O7 | AB7: =Assumptions!$C$23*(1+Assumptions!$C$24)^2 | AC7: =Assumptions!$C$23*(1+Assumptions!$C$24)^2 | AD7: =Assumptions!$C$23*(1+Assumptions!$C$24)^2 | AE7: =Assumptions!$C$23*(1+Assumptions!$C$24)^2 | AF7: =Assumptions!$C$23*(1+Assumptions!$C$24)^2 | AG7: =Assumptions!$C$23*(1+Assumptions!$C$24)^2 | AH7: =Assumptions!$C$23*(1+Assumptions!$C$24)^2 | AI7: =Assumptions!$C$23*(1+Assumptions!$C$24)^2 | ... AM7: =Assumptions!$C$23*(1+Assumptions!$C$24)^2 | AN7: =AB7 | AO7: =Assumptions!$C$23*(1+Assumptions!$C$24)^3 | AP7: =Assumptions!$C$23*(1+Assumptions!$C$24)^3 | AQ7: =Assumptions!$C$23*(1+Assumptions!$C$24)^3 | AR7: =Assumptions!$C$23*(1+Assumptions!$C$24)^3 | AS7: =Assumptions!$C$23*(1+Assumptions!$C$24)^3 | AT7: =Assumptions!$C$23*(1+Assumptions!$C$24)^3 | AU7: =Assumptions!$C$23*(1+Assumptions!$C$24)^3 | AV7: =Assumptions!$C$23*(1+Assumptions!$C$24)^3 | ... AZ7: =Assumptions!$C$23*(1+Assumptions!$C$24)^3 | BA7: =AO7 | BB7: =Assumptions!$C$23*(1+Assumptions!$C$24)^4 | BC7: =Assumptions!$C$23*(1+Assumptions!$C$24)^4 | BD7: =Assumptions!$C$23*(1+Assumptions!$C$24)^4 | BE7: =Assumptions!$C$23*(1+Assumptions!$C$24)^4 | BF7: =Assumptions!$C$23*(1+Assumptions!$C$24)^4 | BG7: =Assumptions!$C$23*(1+Assumptions!$C$24)^4 | BH7: =Assumptions!$C$23*(1+Assumptions!$C$24)^4 | BI7: =Assumptions!$C$23*(1+Assumptions!$C$24)^4 | ... BM7: =Assumptions!$C$23*(1+Assumptions!$C$24)^4 | BN7: =BB7
A8: Trips / consignments revenue | B8: =B6*B7 | C8: =C6*C7 | D8: =D6*D7 | E8: =E6*E7 | F8: =F6*F7 | G8: =G6*G7 | H8: =H6*H7 | I8: =I6*I7 | ... M8: =M6*M7 | N8: =SUM(B8:M8) | O8: =O6*O7 | P8: =P6*P7 | Q8: =Q6*Q7 | R8: =R6*R7 | S8: =S6*S7 | T8: =T6*T7 | U8: =U6*U7 | V8: =V6*V7 | ... Z8: =Z6*Z7 | AA8: =SUM(O8:Z8) | AB8: =AB6*AB7 | AC8: =AC6*AC7 | AD8: =AD6*AD7 | AE8: =AE6*AE7 | AF8: =AF6*AF7 | AG8: =AG6*AG7 | AH8: =AH6*AH7 | AI8: =AI6*AI7 | ... AM8: =AM6*AM7 | AN8: =SUM(AB8:AM8) | AO8: =AO6*AO7 | AP8: =AP6*AP7 | AQ8: =AQ6*AQ7 | AR8: =AR6*AR7 | AS8: =AS6*AS7 | AT8: =AT6*AT7 | AU8: =AU6*AU7 | AV8: =AV6*AV7 | ... AZ8: =AZ6*AZ7 | BA8: =SUM(AO8:AZ8) | BB8: =BB6*BB7 | BC8: =BC6*BC7 | BD8: =BD6*BD7 | BE8: =BE6*BE7 | BF8: =BF6*BF7 | BG8: =BG6*BG7 | BH8: =BH6*BH7 | BI8: =BI6*BI7 | ... BM8: =BM6*BM7 | BN8: =SUM(BB8:BM8)
A10: Warehousing / Storage — units | B10: =Assumptions!$C$66*Assumptions!$C$18/12 | C10: =Assumptions!$C$66*Assumptions!$C$18/12 | D10: =Assumptions!$C$66*Assumptions!$C$18/12 | E10: =Assumptions!$C$66*Assumptions!$C$18/12 | F10: =Assumptions!$C$66*Assumptions!$C$18/12 | G10: =Assumptions!$C$66*Assumptions!$C$18/12 | H10: =Assumptions!$C$66*Assumptions!$C$18/12 | I10: =Assumptions!$C$66*Assumptions!$C$18/12 | ... M10: =Assumptions!$C$66*Assumptions!$C$18/12 | N10: =SUM(B10:M10) | O10: =Assumptions!$C$66*Assumptions!$D$18/12 | P10: =Assumptions!$C$66*Assumptions!$D$18/12 | Q10: =Assumptions!$C$66*Assumptions!$D$18/12 | R10: =Assumptions!$C$66*Assumptions!$D$18/12 | S10: =Assumptions!$C$66*Assumptions!$D$18/12 | T10: =Assumptions!$C$66*Assumptions!$D$18/12 | U10: =Assumptions!$C$66*Assumptions!$D$18/12 | V10: =Assumptions!$C$66*Assumptions!$D$18/12 | ... Z10: =Assumptions!$C$66*Assumptions!$D$18/12 | AA10: =SUM(O10:Z10) | AB10: =Assumptions!$C$66*Assumptions!$E$18/12 | AC10: =Assumptions!$C$66*Assumptions!$E$18/12 | AD10: =Assumptions!$C$66*Assumptions!$E$18/12 | AE10: =Assumptions!$C$66*Assumptions!$E$18/12 | AF10: =Assumptions!$C$66*Assumptions!$E$18/12 | AG10: =Assumptions!$C$66*Assumptions!$E$18/12 | AH10: =Assumptions!$C$66*Assumptions!$E$18/12 | AI10: =Assumptions!$C$66*Assumptions!$E$18/12 | ... AM10: =Assumptions!$C$66*Assumptions!$E$18/12 | AN10: =SUM(AB10:AM10) | AO10: =Assumptions!$C$66*Assumptions!$F$18/12 | AP10: =Assumptions!$C$66*Assumptions!$F$18/12 | AQ10: =Assumptions!$C$66*Assumptions!$F$18/12 | AR10: =Assumptions!$C$66*Assumptions!$F$18/12 | AS10: =Assumptions!$C$66*Assumptions!$F$18/12 | AT10: =Assumptions!$C$66*Assumptions!$F$18/12 | AU10: =Assumptions!$C$66*Assumptions!$F$18/12 | AV10: =Assumptions!$C$66*Assumptions!$F$18/12 | ... AZ10: =Assumptions!$C$66*Assumptions!$F$18/12 | BA10: =SUM(AO10:AZ10) | BB10: =Assumptions!$C$66*Assumptions!$G$18/12 | BC10: =Assumptions!$C$66*Assumptions!$G$18/12 | BD10: =Assumptions!$C$66*Assumptions!$G$18/12 | BE10: =Assumptions!$C$66*Assumptions!$G$18/12 | BF10: =Assumptions!$C$66*Assumptions!$G$18/12 | BG10: =Assumptions!$C$66*Assumptions!$G$18/12 | BH10: =Assumptions!$C$66*Assumptions!$G$18/12 | BI10: =Assumptions!$C$66*Assumptions!$G$18/12 | ... BM10: =Assumptions!$C$66*Assumptions!$G$18/12 | BN10: =SUM(BB10:BM10)
A11: Warehousing / Storage — ₹ / unit | B11: =Assumptions!$D$66*(1+Assumptions!$C$24)^0 | C11: =Assumptions!$D$66*(1+Assumptions!$C$24)^0 | D11: =Assumptions!$D$66*(1+Assumptions!$C$24)^0 | E11: =Assumptions!$D$66*(1+Assumptions!$C$24)^0 | F11: =Assumptions!$D$66*(1+Assumptions!$C$24)^0 | G11: =Assumptions!$D$66*(1+Assumptions!$C$24)^0 | H11: =Assumptions!$D$66*(1+Assumptions!$C$24)^0 | I11: =Assumptions!$D$66*(1+Assumptions!$C$24)^0 | ... M11: =Assumptions!$D$66*(1+Assumptions!$C$24)^0 | N11: =B11 | O11: =Assumptions!$D$66*(1+Assumptions!$C$24)^1 | P11: =Assumptions!$D$66*(1+Assumptions!$C$24)^1 | Q11: =Assumptions!$D$66*(1+Assumptions!$C$24)^1 | R11: =Assumptions!$D$66*(1+Assumptions!$C$24)^1 | S11: =Assumptions!$D$66*(1+Assumptions!$C$24)^1 | T11: =Assumptions!$D$66*(1+Assumptions!$C$24)^1 | U11: =Assumptions!$D$66*(1+Assumptions!$C$24)^1 | V11: =Assumptions!$D$66*(1+Assumptions!$C$24)^1 | ... Z11: =Assumptions!$D$66*(1+Assumptions!$C$24)^1 | AA11: =O11 | AB11: =Assumptions!$D$66*(1+Assumptions!$C$24)^2 | AC11: =Assumptions!$D$66*(1+Assumptions!$C$24)^2 | AD11: =Assumptions!$D$66*(1+Assumptions!$C$24)^2 | AE11: =Assumptions!$D$66*(1+Assumptions!$C$24)^2 | AF11: =Assumptions!$D$66*(1+Assumptions!$C$24)^2 | AG11: =Assumptions!$D$66*(1+Assumptions!$C$24)^2 | AH11: =Assumptions!$D$66*(1+Assumptions!$C$24)^2 | AI11: =Assumptions!$D$66*(1+Assumptions!$C$24)^2 | ... AM11: =Assumptions!$D$66*(1+Assumptions!$C$24)^2 | AN11: =AB11 | AO11: =Assumptions!$D$66*(1+Assumptions!$C$24)^3 | AP11: =Assumptions!$D$66*(1+Assumptions!$C$24)^3 | AQ11: =Assumptions!$D$66*(1+Assumptions!$C$24)^3 | AR11: =Assumptions!$D$66*(1+Assumptions!$C$24)^3 | AS11: =Assumptions!$D$66*(1+Assumptions!$C$24)^3 | AT11: =Assumptions!$D$66*(1+Assumptions!$C$24)^3 | AU11: =Assumptions!$D$66*(1+Assumptions!$C$24)^3 | AV11: =Assumptions!$D$66*(1+Assumptions!$C$24)^3 | ... AZ11: =Assumptions!$D$66*(1+Assumptions!$C$24)^3 | BA11: =AO11 | BB11: =Assumptions!$D$66*(1+Assumptions!$C$24)^4 | BC11: =Assumptions!$D$66*(1+Assumptions!$C$24)^4 | BD11: =Assumptions!$D$66*(1+Assumptions!$C$24)^4 | BE11: =Assumptions!$D$66*(1+Assumptions!$C$24)^4 | BF11: =Assumptions!$D$66*(1+Assumptions!$C$24)^4 | BG11: =Assumptions!$D$66*(1+Assumptions!$C$24)^4 | BH11: =Assumptions!$D$66*(1+Assumptions!$C$24)^4 | BI11: =Assumptions!$D$66*(1+Assumptions!$C$24)^4 | ... BM11: =Assumptions!$D$66*(1+Assumptions!$C$24)^4 | BN11: =BB11
A12: Warehousing / Storage | B12: =B10*B11 | C12: =C10*C11 | D12: =D10*D11 | E12: =E10*E11 | F12: =F10*F11 | G12: =G10*G11 | H12: =H10*H11 | I12: =I10*I11 | ... M12: =M10*M11 | N12: =SUM(B12:M12) | O12: =O10*O11 | P12: =P10*P11 | Q12: =Q10*Q11 | R12: =R10*R11 | S12: =S10*S11 | T12: =T10*T11 | U12: =U10*U11 | V12: =V10*V11 | ... Z12: =Z10*Z11 | AA12: =SUM(O12:Z12) | AB12: =AB10*AB11 | AC12: =AC10*AC11 | AD12: =AD10*AD11 | AE12: =AE10*AE11 | AF12: =AF10*AF11 | AG12: =AG10*AG11 | AH12: =AH10*AH11 | AI12: =AI10*AI11 | ... AM12: =AM10*AM11 | AN12: =SUM(AB12:AM12) | AO12: =AO10*AO11 | AP12: =AP10*AP11 | AQ12: =AQ10*AQ11 | AR12: =AR10*AR11 | AS12: =AS10*AS11 | AT12: =AT10*AT11 | AU12: =AU10*AU11 | AV12: =AV10*AV11 | ... AZ12: =AZ10*AZ11 | BA12: =SUM(AO12:AZ12) | BB12: =BB10*BB11 | BC12: =BC10*BC11 | BD12: =BD10*BD11 | BE12: =BE10*BE11 | BF12: =BF10*BF11 | BG12: =BG10*BG11 | BH12: =BH10*BH11 | BI12: =BI10*BI11 | ... BM12: =BM10*BM11 | BN12: =SUM(BB12:BM12)
A14: Value-added logistics — units | B14: =Assumptions!$C$67*Assumptions!$C$18/12 | C14: =Assumptions!$C$67*Assumptions!$C$18/12 | D14: =Assumptions!$C$67*Assumptions!$C$18/12 | E14: =Assumptions!$C$67*Assumptions!$C$18/12 | F14: =Assumptions!$C$67*Assumptions!$C$18/12 | G14: =Assumptions!$C$67*Assumptions!$C$18/12 | H14: =Assumptions!$C$67*Assumptions!$C$18/12 | I14: =Assumptions!$C$67*Assumptions!$C$18/12 | ... M14: =Assumptions!$C$67*Assumptions!$C$18/12 | N14: =SUM(B14:M14) | O14: =Assumptions!$C$67*Assumptions!$D$18/12 | P14: =Assumptions!$C$67*Assumptions!$D$18/12 | Q14: =Assumptions!$C$67*Assumptions!$D$18/12 | R14: =Assumptions!$C$67*Assumptions!$D$18/12 | S14: =Assumptions!$C$67*Assumptions!$D$18/12 | T14: =Assumptions!$C$67*Assumptions!$D$18/12 | U14: =Assumptions!$C$67*Assumptions!$D$18/12 | V14: =Assumptions!$C$67*Assumptions!$D$18/12 | ... Z14: =Assumptions!$C$67*Assumptions!$D$18/12 | AA14: =SUM(O14:Z14) | AB14: =Assumptions!$C$67*Assumptions!$E$18/12 | AC14: =Assumptions!$C$67*Assumptions!$E$18/12 | AD14: =Assumptions!$C$67*Assumptions!$E$18/12 | AE14: =Assumptions!$C$67*Assumptions!$E$18/12 | AF14: =Assumptions!$C$67*Assumptions!$E$18/12 | AG14: =Assumptions!$C$67*Assumptions!$E$18/12 | AH14: =Assumptions!$C$67*Assumptions!$E$18/12 | AI14: =Assumptions!$C$67*Assumptions!$E$18/12 | ... AM14: =Assumptions!$C$67*Assumptions!$E$18/12 | AN14: =SUM(AB14:AM14) | AO14: =Assumptions!$C$67*Assumptions!$F$18/12 | AP14: =Assumptions!$C$67*Assumptions!$F$18/12 | AQ14: =Assumptions!$C$67*Assumptions!$F$18/12 | AR14: =Assumptions!$C$67*Assumptions!$F$18/12 | AS14: =Assumptions!$C$67*Assumptions!$F$18/12 | AT14: =Assumptions!$C$67*Assumptions!$F$18/12 | AU14: =Assumptions!$C$67*Assumptions!$F$18/12 | AV14: =Assumptions!$C$67*Assumptions!$F$18/12 | ... AZ14: =Assumptions!$C$67*Assumptions!$F$18/12 | BA14: =SUM(AO14:AZ14) | BB14: =Assumptions!$C$67*Assumptions!$G$18/12 | BC14: =Assumptions!$C$67*Assumptions!$G$18/12 | BD14: =Assumptions!$C$67*Assumptions!$G$18/12 | BE14: =Assumptions!$C$67*Assumptions!$G$18/12 | BF14: =Assumptions!$C$67*Assumptions!$G$18/12 | BG14: =Assumptions!$C$67*Assumptions!$G$18/12 | BH14: =Assumptions!$C$67*Assumptions!$G$18/12 | BI14: =Assumptions!$C$67*Assumptions!$G$18/12 | ... BM14: =Assumptions!$C$67*Assumptions!$G$18/12 | BN14: =SUM(BB14:BM14)
A15: Value-added logistics — ₹ / unit | B15: =Assumptions!$D$67*(1+Assumptions!$C$24)^0 | C15: =Assumptions!$D$67*(1+Assumptions!$C$24)^0 | D15: =Assumptions!$D$67*(1+Assumptions!$C$24)^0 | E15: =Assumptions!$D$67*(1+Assumptions!$C$24)^0 | F15: =Assumptions!$D$67*(1+Assumptions!$C$24)^0 | G15: =Assumptions!$D$67*(1+Assumptions!$C$24)^0 | H15: =Assumptions!$D$67*(1+Assumptions!$C$24)^0 | I15: =Assumptions!$D$67*(1+Assumptions!$C$24)^0 | ... M15: =Assumptions!$D$67*(1+Assumptions!$C$24)^0 | N15: =B15 | O15: =Assumptions!$D$67*(1+Assumptions!$C$24)^1 | P15: =Assumptions!$D$67*(1+Assumptions!$C$24)^1 | Q15: =Assumptions!$D$67*(1+Assumptions!$C$24)^1 | R15: =Assumptions!$D$67*(1+Assumptions!$C$24)^1 | S15: =Assumptions!$D$67*(1+Assumptions!$C$24)^1 | T15: =Assumptions!$D$67*(1+Assumptions!$C$24)^1 | U15: =Assumptions!$D$67*(1+Assumptions!$C$24)^1 | V15: =Assumptions!$D$67*(1+Assumptions!$C$24)^1 | ... Z15: =Assumptions!$D$67*(1+Assumptions!$C$24)^1 | AA15: =O15 | AB15: =Assumptions!$D$67*(1+Assumptions!$C$24)^2 | AC15: =Assumptions!$D$67*(1+Assumptions!$C$24)^2 | AD15: =Assumptions!$D$67*(1+Assumptions!$C$24)^2 | AE15: =Assumptions!$D$67*(1+Assumptions!$C$24)^2 | AF15: =Assumptions!$D$67*(1+Assumptions!$C$24)^2 | AG15: =Assumptions!$D$67*(1+Assumptions!$C$24)^2 | AH15: =Assumptions!$D$67*(1+Assumptions!$C$24)^2 | AI15: =Assumptions!$D$67*(1+Assumptions!$C$24)^2 | ... AM15: =Assumptions!$D$67*(1+Assumptions!$C$24)^2 | AN15: =AB15 | AO15: =Assumptions!$D$67*(1+Assumptions!$C$24)^3 | AP15: =Assumptions!$D$67*(1+Assumptions!$C$24)^3 | AQ15: =Assumptions!$D$67*(1+Assumptions!$C$24)^3 | AR15: =Assumptions!$D$67*(1+Assumptions!$C$24)^3 | AS15: =Assumptions!$D$67*(1+Assumptions!$C$24)^3 | AT15: =Assumptions!$D$67*(1+Assumptions!$C$24)^3 | AU15: =Assumptions!$D$67*(1+Assumptions!$C$24)^3 | AV15: =Assumptions!$D$67*(1+Assumptions!$C$24)^3 | ... AZ15: =Assumptions!$D$67*(1+Assumptions!$C$24)^3 | BA15: =AO15 | BB15: =Assumptions!$D$67*(1+Assumptions!$C$24)^4 | BC15: =Assumptions!$D$67*(1+Assumptions!$C$24)^4 | BD15: =Assumptions!$D$67*(1+Assumptions!$C$24)^4 | BE15: =Assumptions!$D$67*(1+Assumptions!$C$24)^4 | BF15: =Assumptions!$D$67*(1+Assumptions!$C$24)^4 | BG15: =Assumptions!$D$67*(1+Assumptions!$C$24)^4 | BH15: =Assumptions!$D$67*(1+Assumptions!$C$24)^4 | BI15: =Assumptions!$D$67*(1+Assumptions!$C$24)^4 | ... BM15: =Assumptions!$D$67*(1+Assumptions!$C$24)^4 | BN15: =BB15
A16: Value-added logistics | B16: =B14*B15 | C16: =C14*C15 | D16: =D14*D15 | E16: =E14*E15 | F16: =F14*F15 | G16: =G14*G15 | H16: =H14*H15 | I16: =I14*I15 | ... M16: =M14*M15 | N16: =SUM(B16:M16) | O16: =O14*O15 | P16: =P14*P15 | Q16: =Q14*Q15 | R16: =R14*R15 | S16: =S14*S15 | T16: =T14*T15 | U16: =U14*U15 | V16: =V14*V15 | ... Z16: =Z14*Z15 | AA16: =SUM(O16:Z16) | AB16: =AB14*AB15 | AC16: =AC14*AC15 | AD16: =AD14*AD15 | AE16: =AE14*AE15 | AF16: =AF14*AF15 | AG16: =AG14*AG15 | AH16: =AH14*AH15 | AI16: =AI14*AI15 | ... AM16: =AM14*AM15 | AN16: =SUM(AB16:AM16) | AO16: =AO14*AO15 | AP16: =AP14*AP15 | AQ16: =AQ14*AQ15 | AR16: =AR14*AR15 | AS16: =AS14*AS15 | AT16: =AT14*AT15 | AU16: =AU14*AU15 | AV16: =AV14*AV15 | ... AZ16: =AZ14*AZ15 | BA16: =SUM(AO16:AZ16) | BB16: =BB14*BB15 | BC16: =BC14*BC15 | BD16: =BD14*BD15 | BE16: =BE14*BE15 | BF16: =BF14*BF15 | BG16: =BG14*BG15 | BH16: =BH14*BH15 | BI16: =BI14*BI15 | ... BM16: =BM14*BM15 | BN16: =SUM(BB16:BM16)
A18: Express / Priority — units | B18: =Assumptions!$C$68*Assumptions!$C$18/12 | C18: =Assumptions!$C$68*Assumptions!$C$18/12 | D18: =Assumptions!$C$68*Assumptions!$C$18/12 | E18: =Assumptions!$C$68*Assumptions!$C$18/12 | F18: =Assumptions!$C$68*Assumptions!$C$18/12 | G18: =Assumptions!$C$68*Assumptions!$C$18/12 | H18: =Assumptions!$C$68*Assumptions!$C$18/12 | I18: =Assumptions!$C$68*Assumptions!$C$18/12 | ... M18: =Assumptions!$C$68*Assumptions!$C$18/12 | N18: =SUM(B18:M18) | O18: =Assumptions!$C$68*Assumptions!$D$18/12 | P18: =Assumptions!$C$68*Assumptions!$D$18/12 | Q18: =Assumptions!$C$68*Assumptions!$D$18/12 | R18: =Assumptions!$C$68*Assumptions!$D$18/12 | S18: =Assumptions!$C$68*Assumptions!$D$18/12 | T18: =Assumptions!$C$68*Assumptions!$D$18/12 | U18: =Assumptions!$C$68*Assumptions!$D$18/12 | V18: =Assumptions!$C$68*Assumptions!$D$18/12 | ... Z18: =Assumptions!$C$68*Assumptions!$D$18/12 | AA18: =SUM(O18:Z18) | AB18: =Assumptions!$C$68*Assumptions!$E$18/12 | AC18: =Assumptions!$C$68*Assumptions!$E$18/12 | AD18: =Assumptions!$C$68*Assumptions!$E$18/12 | AE18: =Assumptions!$C$68*Assumptions!$E$18/12 | AF18: =Assumptions!$C$68*Assumptions!$E$18/12 | AG18: =Assumptions!$C$68*Assumptions!$E$18/12 | AH18: =Assumptions!$C$68*Assumptions!$E$18/12 | AI18: =Assumptions!$C$68*Assumptions!$E$18/12 | ... AM18: =Assumptions!$C$68*Assumptions!$E$18/12 | AN18: =SUM(AB18:AM18) | AO18: =Assumptions!$C$68*Assumptions!$F$18/12 | AP18: =Assumptions!$C$68*Assumptions!$F$18/12 | AQ18: =Assumptions!$C$68*Assumptions!$F$18/12 | AR18: =Assumptions!$C$68*Assumptions!$F$18/12 | AS18: =Assumptions!$C$68*Assumptions!$F$18/12 | AT18: =Assumptions!$C$68*Assumptions!$F$18/12 | AU18: =Assumptions!$C$68*Assumptions!$F$18/12 | AV18: =Assumptions!$C$68*Assumptions!$F$18/12 | ... AZ18: =Assumptions!$C$68*Assumptions!$F$18/12 | BA18: =SUM(AO18:AZ18) | BB18: =Assumptions!$C$68*Assumptions!$G$18/12 | BC18: =Assumptions!$C$68*Assumptions!$G$18/12 | BD18: =Assumptions!$C$68*Assumptions!$G$18/12 | BE18: =Assumptions!$C$68*Assumptions!$G$18/12 | BF18: =Assumptions!$C$68*Assumptions!$G$18/12 | BG18: =Assumptions!$C$68*Assumptions!$G$18/12 | BH18: =Assumptions!$C$68*Assumptions!$G$18/12 | BI18: =Assumptions!$C$68*Assumptions!$G$18/12 | ... BM18: =Assumptions!$C$68*Assumptions!$G$18/12 | BN18: =SUM(BB18:BM18)
A19: Express / Priority — ₹ / unit | B19: =Assumptions!$D$68*(1+Assumptions!$C$24)^0 | C19: =Assumptions!$D$68*(1+Assumptions!$C$24)^0 | D19: =Assumptions!$D$68*(1+Assumptions!$C$24)^0 | E19: =Assumptions!$D$68*(1+Assumptions!$C$24)^0 | F19: =Assumptions!$D$68*(1+Assumptions!$C$24)^0 | G19: =Assumptions!$D$68*(1+Assumptions!$C$24)^0 | H19: =Assumptions!$D$68*(1+Assumptions!$C$24)^0 | I19: =Assumptions!$D$68*(1+Assumptions!$C$24)^0 | ... M19: =Assumptions!$D$68*(1+Assumptions!$C$24)^0 | N19: =B19 | O19: =Assumptions!$D$68*(1+Assumptions!$C$24)^1 | P19: =Assumptions!$D$68*(1+Assumptions!$C$24)^1 | Q19: =Assumptions!$D$68*(1+Assumptions!$C$24)^1 | R19: =Assumptions!$D$68*(1+Assumptions!$C$24)^1 | S19: =Assumptions!$D$68*(1+Assumptions!$C$24)^1 | T19: =Assumptions!$D$68*(1+Assumptions!$C$24)^1 | U19: =Assumptions!$D$68*(1+Assumptions!$C$24)^1 | V19: =Assumptions!$D$68*(1+Assumptions!$C$24)^1 | ... Z19: =Assumptions!$D$68*(1+Assumptions!$C$24)^1 | AA19: =O19 | AB19: =Assumptions!$D$68*(1+Assumptions!$C$24)^2 | AC19: =Assumptions!$D$68*(1+Assumptions!$C$24)^2 | AD19: =Assumptions!$D$68*(1+Assumptions!$C$24)^2 | AE19: =Assumptions!$D$68*(1+Assumptions!$C$24)^2 | AF19: =Assumptions!$D$68*(1+Assumptions!$C$24)^2 | AG19: =Assumptions!$D$68*(1+Assumptions!$C$24)^2 | AH19: =Assumptions!$D$68*(1+Assumptions!$C$24)^2 | AI19: =Assumptions!$D$68*(1+Assumptions!$C$24)^2 | ... AM19: =Assumptions!$D$68*(1+Assumptions!$C$24)^2 | AN19: =AB19 | AO19: =Assumptions!$D$68*(1+Assumptions!$C$24)^3 | AP19: =Assumptions!$D$68*(1+Assumptions!$C$24)^3 | AQ19: =Assumptions!$D$68*(1+Assumptions!$C$24)^3 | AR19: =Assumptions!$D$68*(1+Assumptions!$C$24)^3 | AS19: =Assumptions!$D$68*(1+Assumptions!$C$24)^3 | AT19: =Assumptions!$D$68*(1+Assumptions!$C$24)^3 | AU19: =Assumptions!$D$68*(1+Assumptions!$C$24)^3 | AV19: =Assumptions!$D$68*(1+Assumptions!$C$24)^3 | ... AZ19: =Assumptions!$D$68*(1+Assumptions!$C$24)^3 | BA19: =AO19 | BB19: =Assumptions!$D$68*(1+Assumptions!$C$24)^4 | BC19: =Assumptions!$D$68*(1+Assumptions!$C$24)^4 | BD19: =Assumptions!$D$68*(1+Assumptions!$C$24)^4 | BE19: =Assumptions!$D$68*(1+Assumptions!$C$24)^4 | BF19: =Assumptions!$D$68*(1+Assumptions!$C$24)^4 | BG19: =Assumptions!$D$68*(1+Assumptions!$C$24)^4 | BH19: =Assumptions!$D$68*(1+Assumptions!$C$24)^4 | BI19: =Assumptions!$D$68*(1+Assumptions!$C$24)^4 | ... BM19: =Assumptions!$D$68*(1+Assumptions!$C$24)^4 | BN19: =BB19
A20: Express / Priority | B20: =B18*B19 | C20: =C18*C19 | D20: =D18*D19 | E20: =E18*E19 | F20: =F18*F19 | G20: =G18*G19 | H20: =H18*H19 | I20: =I18*I19 | ... M20: =M18*M19 | N20: =SUM(B20:M20) | O20: =O18*O19 | P20: =P18*P19 | Q20: =Q18*Q19 | R20: =R18*R19 | S20: =S18*S19 | T20: =T18*T19 | U20: =U18*U19 | V20: =V18*V19 | ... Z20: =Z18*Z19 | AA20: =SUM(O20:Z20) | AB20: =AB18*AB19 | AC20: =AC18*AC19 | AD20: =AD18*AD19 | AE20: =AE18*AE19 | AF20: =AF18*AF19 | AG20: =AG18*AG19 | AH20: =AH18*AH19 | AI20: =AI18*AI19 | ... AM20: =AM18*AM19 | AN20: =SUM(AB20:AM20) | AO20: =AO18*AO19 | AP20: =AP18*AP19 | AQ20: =AQ18*AQ19 | AR20: =AR18*AR19 | AS20: =AS18*AS19 | AT20: =AT18*AT19 | AU20: =AU18*AU19 | AV20: =AV18*AV19 | ... AZ20: =AZ18*AZ19 | BA20: =SUM(AO20:AZ20) | BB20: =BB18*BB19 | BC20: =BC18*BC19 | BD20: =BD18*BD19 | BE20: =BE18*BE19 | BF20: =BF18*BF19 | BG20: =BG18*BG19 | BH20: =BH18*BH19 | BI20: =BI18*BI19 | ... BM20: =BM18*BM19 | BN20: =SUM(BB20:BM20)
A22: Other revenue — units | B22: =Assumptions!$C$69*Assumptions!$C$18/12 | C22: =Assumptions!$C$69*Assumptions!$C$18/12 | D22: =Assumptions!$C$69*Assumptions!$C$18/12 | E22: =Assumptions!$C$69*Assumptions!$C$18/12 | F22: =Assumptions!$C$69*Assumptions!$C$18/12 | G22: =Assumptions!$C$69*Assumptions!$C$18/12 | H22: =Assumptions!$C$69*Assumptions!$C$18/12 | I22: =Assumptions!$C$69*Assumptions!$C$18/12 | ... M22: =Assumptions!$C$69*Assumptions!$C$18/12 | N22: =SUM(B22:M22) | O22: =Assumptions!$C$69*Assumptions!$D$18/12 | P22: =Assumptions!$C$69*Assumptions!$D$18/12 | Q22: =Assumptions!$C$69*Assumptions!$D$18/12 | R22: =Assumptions!$C$69*Assumptions!$D$18/12 | S22: =Assumptions!$C$69*Assumptions!$D$18/12 | T22: =Assumptions!$C$69*Assumptions!$D$18/12 | U22: =Assumptions!$C$69*Assumptions!$D$18/12 | V22: =Assumptions!$C$69*Assumptions!$D$18/12 | ... Z22: =Assumptions!$C$69*Assumptions!$D$18/12 | AA22: =SUM(O22:Z22) | AB22: =Assumptions!$C$69*Assumptions!$E$18/12 | AC22: =Assumptions!$C$69*Assumptions!$E$18/12 | AD22: =Assumptions!$C$69*Assumptions!$E$18/12 | AE22: =Assumptions!$C$69*Assumptions!$E$18/12 | AF22: =Assumptions!$C$69*Assumptions!$E$18/12 | AG22: =Assumptions!$C$69*Assumptions!$E$18/12 | AH22: =Assumptions!$C$69*Assumptions!$E$18/12 | AI22: =Assumptions!$C$69*Assumptions!$E$18/12 | ... AM22: =Assumptions!$C$69*Assumptions!$E$18/12 | AN22: =SUM(AB22:AM22) | AO22: =Assumptions!$C$69*Assumptions!$F$18/12 | AP22: =Assumptions!$C$69*Assumptions!$F$18/12 | AQ22: =Assumptions!$C$69*Assumptions!$F$18/12 | AR22: =Assumptions!$C$69*Assumptions!$F$18/12 | AS22: =Assumptions!$C$69*Assumptions!$F$18/12 | AT22: =Assumptions!$C$69*Assumptions!$F$18/12 | AU22: =Assumptions!$C$69*Assumptions!$F$18/12 | AV22: =Assumptions!$C$69*Assumptions!$F$18/12 | ... AZ22: =Assumptions!$C$69*Assumptions!$F$18/12 | BA22: =SUM(AO22:AZ22) | BB22: =Assumptions!$C$69*Assumptions!$G$18/12 | BC22: =Assumptions!$C$69*Assumptions!$G$18/12 | BD22: =Assumptions!$C$69*Assumptions!$G$18/12 | BE22: =Assumptions!$C$69*Assumptions!$G$18/12 | BF22: =Assumptions!$C$69*Assumptions!$G$18/12 | BG22: =Assumptions!$C$69*Assumptions!$G$18/12 | BH22: =Assumptions!$C$69*Assumptions!$G$18/12 | BI22: =Assumptions!$C$69*Assumptions!$G$18/12 | ... BM22: =Assumptions!$C$69*Assumptions!$G$18/12 | BN22: =SUM(BB22:BM22)
A23: Other revenue — ₹ / unit | B23: =Assumptions!$D$69*(1+Assumptions!$C$24)^0 | C23: =Assumptions!$D$69*(1+Assumptions!$C$24)^0 | D23: =Assumptions!$D$69*(1+Assumptions!$C$24)^0 | E23: =Assumptions!$D$69*(1+Assumptions!$C$24)^0 | F23: =Assumptions!$D$69*(1+Assumptions!$C$24)^0 | G23: =Assumptions!$D$69*(1+Assumptions!$C$24)^0 | H23: =Assumptions!$D$69*(1+Assumptions!$C$24)^0 | I23: =Assumptions!$D$69*(1+Assumptions!$C$24)^0 | ... M23: =Assumptions!$D$69*(1+Assumptions!$C$24)^0 | N23: =B23 | O23: =Assumptions!$D$69*(1+Assumptions!$C$24)^1 | P23: =Assumptions!$D$69*(1+Assumptions!$C$24)^1 | Q23: =Assumptions!$D$69*(1+Assumptions!$C$24)^1 | R23: =Assumptions!$D$69*(1+Assumptions!$C$24)^1 | S23: =Assumptions!$D$69*(1+Assumptions!$C$24)^1 | T23: =Assumptions!$D$69*(1+Assumptions!$C$24)^1 | U23: =Assumptions!$D$69*(1+Assumptions!$C$24)^1 | V23: =Assumptions!$D$69*(1+Assumptions!$C$24)^1 | ... Z23: =Assumptions!$D$69*(1+Assumptions!$C$24)^1 | AA23: =O23 | AB23: =Assumptions!$D$69*(1+Assumptions!$C$24)^2 | AC23: =Assumptions!$D$69*(1+Assumptions!$C$24)^2 | AD23: =Assumptions!$D$69*(1+Assumptions!$C$24)^2 | AE23: =Assumptions!$D$69*(1+Assumptions!$C$24)^2 | AF23: =Assumptions!$D$69*(1+Assumptions!$C$24)^2 | AG23: =Assumptions!$D$69*(1+Assumptions!$C$24)^2 | AH23: =Assumptions!$D$69*(1+Assumptions!$C$24)^2 | AI23: =Assumptions!$D$69*(1+Assumptions!$C$24)^2 | ... AM23: =Assumptions!$D$69*(1+Assumptions!$C$24)^2 | AN23: =AB23 | AO23: =Assumptions!$D$69*(1+Assumptions!$C$24)^3 | AP23: =Assumptions!$D$69*(1+Assumptions!$C$24)^3 | AQ23: =Assumptions!$D$69*(1+Assumptions!$C$24)^3 | AR23: =Assumptions!$D$69*(1+Assumptions!$C$24)^3 | AS23: =Assumptions!$D$69*(1+Assumptions!$C$24)^3 | AT23: =Assumptions!$D$69*(1+Assumptions!$C$24)^3 | AU23: =Assumptions!$D$69*(1+Assumptions!$C$24)^3 | AV23: =Assumptions!$D$69*(1+Assumptions!$C$24)^3 | ... AZ23: =Assumptions!$D$69*(1+Assumptions!$C$24)^3 | BA23: =AO23 | BB23: =Assumptions!$D$69*(1+Assumptions!$C$24)^4 | BC23: =Assumptions!$D$69*(1+Assumptions!$C$24)^4 | BD23: =Assumptions!$D$69*(1+Assumptions!$C$24)^4 | BE23: =Assumptions!$D$69*(1+Assumptions!$C$24)^4 | BF23: =Assumptions!$D$69*(1+Assumptions!$C$24)^4 | BG23: =Assumptions!$D$69*(1+Assumptions!$C$24)^4 | BH23: =Assumptions!$D$69*(1+Assumptions!$C$24)^4 | BI23: =Assumptions!$D$69*(1+Assumptions!$C$24)^4 | ... BM23: =Assumptions!$D$69*(1+Assumptions!$C$24)^4 | BN23: =BB23
A24: Other revenue | B24: =B22*B23 | C24: =C22*C23 | D24: =D22*D23 | E24: =E22*E23 | F24: =F22*F23 | G24: =G22*G23 | H24: =H22*H23 | I24: =I22*I23 | ... M24: =M22*M23 | N24: =SUM(B24:M24) | O24: =O22*O23 | P24: =P22*P23 | Q24: =Q22*Q23 | R24: =R22*R23 | S24: =S22*S23 | T24: =T22*T23 | U24: =U22*U23 | V24: =V22*V23 | ... Z24: =Z22*Z23 | AA24: =SUM(O24:Z24) | AB24: =AB22*AB23 | AC24: =AC22*AC23 | AD24: =AD22*AD23 | AE24: =AE22*AE23 | AF24: =AF22*AF23 | AG24: =AG22*AG23 | AH24: =AH22*AH23 | AI24: =AI22*AI23 | ... AM24: =AM22*AM23 | AN24: =SUM(AB24:AM24) | AO24: =AO22*AO23 | AP24: =AP22*AP23 | AQ24: =AQ22*AQ23 | AR24: =AR22*AR23 | AS24: =AS22*AS23 | AT24: =AT22*AT23 | AU24: =AU22*AU23 | AV24: =AV22*AV23 | ... AZ24: =AZ22*AZ23 | BA24: =SUM(AO24:AZ24) | BB24: =BB22*BB23 | BC24: =BC22*BC23 | BD24: =BD22*BD23 | BE24: =BE22*BE23 | BF24: =BF22*BF23 | BG24: =BG22*BG23 | BH24: =BH22*BH23 | BI24: =BI22*BI23 | ... BM24: =BM22*BM23 | BN24: =SUM(BB24:BM24)
A26: TOTAL REVENUE | B26: =B8+B12+B16+B20+B24 | C26: =C8+C12+C16+C20+C24 | D26: =D8+D12+D16+D20+D24 | E26: =E8+E12+E16+E20+E24 | F26: =F8+F12+F16+F20+F24 | G26: =G8+G12+G16+G20+G24 | H26: =H8+H12+H16+H20+H24 | I26: =I8+I12+I16+I20+I24 | ... M26: =M8+M12+M16+M20+M24 | N26: =SUM(B26:M26) | O26: =O8+O12+O16+O20+O24 | P26: =P8+P12+P16+P20+P24 | Q26: =Q8+Q12+Q16+Q20+Q24 | R26: =R8+R12+R16+R20+R24 | S26: =S8+S12+S16+S20+S24 | T26: =T8+T12+T16+T20+T24 | U26: =U8+U12+U16+U20+U24 | V26: =V8+V12+V16+V20+V24 | ... Z26: =Z8+Z12+Z16+Z20+Z24 | AA26: =SUM(O26:Z26) | AB26: =AB8+AB12+AB16+AB20+AB24 | AC26: =AC8+AC12+AC16+AC20+AC24 | AD26: =AD8+AD12+AD16+AD20+AD24 | AE26: =AE8+AE12+AE16+AE20+AE24 | AF26: =AF8+AF12+AF16+AF20+AF24 | AG26: =AG8+AG12+AG16+AG20+AG24 | AH26: =AH8+AH12+AH16+AH20+AH24 | AI26: =AI8+AI12+AI16+AI20+AI24 | ... AM26: =AM8+AM12+AM16+AM20+AM24 | AN26: =SUM(AB26:AM26) | AO26: =AO8+AO12+AO16+AO20+AO24 | AP26: =AP8+AP12+AP16+AP20+AP24 | AQ26: =AQ8+AQ12+AQ16+AQ20+AQ24 | AR26: =AR8+AR12+AR16+AR20+AR24 | AS26: =AS8+AS12+AS16+AS20+AS24 | AT26: =AT8+AT12+AT16+AT20+AT24 | AU26: =AU8+AU12+AU16+AU20+AU24 | AV26: =AV8+AV12+AV16+AV20+AV24 | ... AZ26: =AZ8+AZ12+AZ16+AZ20+AZ24 | BA26: =SUM(AO26:AZ26) | BB26: =BB8+BB12+BB16+BB20+BB24 | BC26: =BC8+BC12+BC16+BC20+BC24 | BD26: =BD8+BD12+BD16+BD20+BD24 | BE26: =BE8+BE12+BE16+BE20+BE24 | BF26: =BF8+BF12+BF16+BF20+BF24 | BG26: =BG8+BG12+BG16+BG20+BG24 | BH26: =BH8+BH12+BH16+BH20+BH24 | BI26: =BI8+BI12+BI16+BI20+BI24 | ... BM26: =BM8+BM12+BM16+BM20+BM24 | BN26: =SUM(BB26:BM26)
A28: REVENUE BY TARGET MARKET SEGMENT (₹)
A29: =IF(Assumptions!$C$58="","",Assumptions!$C$58) | B29: =IF(Assumptions!$C$58="","",IFERROR(B26*Assumptions!$D$58,0)) | C29: =IF(Assumptions!$C$58="","",IFERROR(C26*Assumptions!$D$58,0)) | D29: =IF(Assumptions!$C$58="","",IFERROR(D26*Assumptions!$D$58,0)) | E29: =IF(Assumptions!$C$58="","",IFERROR(E26*Assumptions!$D$58,0)) | F29: =IF(Assumptions!$C$58="","",IFERROR(F26*Assumptions!$D$58,0)) | G29: =IF(Assumptions!$C$58="","",IFERROR(G26*Assumptions!$D$58,0)) | H29: =IF(Assumptions!$C$58="","",IFERROR(H26*Assumptions!$D$58,0)) | I29: =IF(Assumptions!$C$58="","",IFERROR(I26*Assumptions!$D$58,0)) | ... M29: =IF(Assumptions!$C$58="","",IFERROR(M26*Assumptions!$D$58,0)) | N29: =SUM(B29:M29) | O29: =IF(Assumptions!$C$58="","",IFERROR(O26*Assumptions!$D$58,0)) | P29: =IF(Assumptions!$C$58="","",IFERROR(P26*Assumptions!$D$58,0)) | Q29: =IF(Assumptions!$C$58="","",IFERROR(Q26*Assumptions!$D$58,0)) | R29: =IF(Assumptions!$C$58="","",IFERROR(R26*Assumptions!$D$58,0)) | S29: =IF(Assumptions!$C$58="","",IFERROR(S26*Assumptions!$D$58,0)) | T29: =IF(Assumptions!$C$58="","",IFERROR(T26*Assumptions!$D$58,0)) | U29: =IF(Assumptions!$C$58="","",IFERROR(U26*Assumptions!$D$58,0)) | V29: =IF(Assumptions!$C$58="","",IFERROR(V26*Assumptions!$D$58,0)) | ... Z29: =IF(Assumptions!$C$58="","",IFERROR(Z26*Assumptions!$D$58,0)) | AA29: =SUM(O29:Z29) | AB29: =IF(Assumptions!$C$58="","",IFERROR(AB26*Assumptions!$D$58,0)) | AC29: =IF(Assumptions!$C$58="","",IFERROR(AC26*Assumptions!$D$58,0)) | AD29: =IF(Assumptions!$C$58="","",IFERROR(AD26*Assumptions!$D$58,0)) | AE29: =IF(Assumptions!$C$58="","",IFERROR(AE26*Assumptions!$D$58,0)) | AF29: =IF(Assumptions!$C$58="","",IFERROR(AF26*Assumptions!$D$58,0)) | AG29: =IF(Assumptions!$C$58="","",IFERROR(AG26*Assumptions!$D$58,0)) | AH29: =IF(Assumptions!$C$58="","",IFERROR(AH26*Assumptions!$D$58,0)) | AI29: =IF(Assumptions!$C$58="","",IFERROR(AI26*Assumptions!$D$58,0)) | ... AM29: =IF(Assumptions!$C$58="","",IFERROR(AM26*Assumptions!$D$58,0)) | AN29: =SUM(AB29:AM29) | AO29: =IF(Assumptions!$C$58="","",IFERROR(AO26*Assumptions!$D$58,0)) | AP29: =IF(Assumptions!$C$58="","",IFERROR(AP26*Assumptions!$D$58,0)) | AQ29: =IF(Assumptions!$C$58="","",IFERROR(AQ26*Assumptions!$D$58,0)) | AR29: =IF(Assumptions!$C$58="","",IFERROR(AR26*Assumptions!$D$58,0)) | AS29: =IF(Assumptions!$C$58="","",IFERROR(AS26*Assumptions!$D$58,0)) | AT29: =IF(Assumptions!$C$58="","",IFERROR(AT26*Assumptions!$D$58,0)) | AU29: =IF(Assumptions!$C$58="","",IFERROR(AU26*Assumptions!$D$58,0)) | AV29: =IF(Assumptions!$C$58="","",IFERROR(AV26*Assumptions!$D$58,0)) | ... AZ29: =IF(Assumptions!$C$58="","",IFERROR(AZ26*Assumptions!$D$58,0)) | BA29: =SUM(AO29:AZ29) | BB29: =IF(Assumptions!$C$58="","",IFERROR(BB26*Assumptions!$D$58,0)) | BC29: =IF(Assumptions!$C$58="","",IFERROR(BC26*Assumptions!$D$58,0)) | BD29: =IF(Assumptions!$C$58="","",IFERROR(BD26*Assumptions!$D$58,0)) | BE29: =IF(Assumptions!$C$58="","",IFERROR(BE26*Assumptions!$D$58,0)) | BF29: =IF(Assumptions!$C$58="","",IFERROR(BF26*Assumptions!$D$58,0)) | BG29: =IF(Assumptions!$C$58="","",IFERROR(BG26*Assumptions!$D$58,0)) | BH29: =IF(Assumptions!$C$58="","",IFERROR(BH26*Assumptions!$D$58,0)) | BI29: =IF(Assumptions!$C$58="","",IFERROR(BI26*Assumptions!$D$58,0)) | ... BM29: =IF(Assumptions!$C$58="","",IFERROR(BM26*Assumptions!$D$58,0)) | BN29: =SUM(BB29:BM29)
A30: =IF(Assumptions!$C$59="","",Assumptions!$C$59) | B30: =IF(Assumptions!$C$59="","",IFERROR(B26*Assumptions!$D$59,0)) | C30: =IF(Assumptions!$C$59="","",IFERROR(C26*Assumptions!$D$59,0)) | D30: =IF(Assumptions!$C$59="","",IFERROR(D26*Assumptions!$D$59,0)) | E30: =IF(Assumptions!$C$59="","",IFERROR(E26*Assumptions!$D$59,0)) | F30: =IF(Assumptions!$C$59="","",IFERROR(F26*Assumptions!$D$59,0)) | G30: =IF(Assumptions!$C$59="","",IFERROR(G26*Assumptions!$D$59,0)) | H30: =IF(Assumptions!$C$59="","",IFERROR(H26*Assumptions!$D$59,0)) | I30: =IF(Assumptions!$C$59="","",IFERROR(I26*Assumptions!$D$59,0)) | ... M30: =IF(Assumptions!$C$59="","",IFERROR(M26*Assumptions!$D$59,0)) | N30: =SUM(B30:M30) | O30: =IF(Assumptions!$C$59="","",IFERROR(O26*Assumptions!$D$59,0)) | P30: =IF(Assumptions!$C$59="","",IFERROR(P26*Assumptions!$D$59,0)) | Q30: =IF(Assumptions!$C$59="","",IFERROR(Q26*Assumptions!$D$59,0)) | R30: =IF(Assumptions!$C$59="","",IFERROR(R26*Assumptions!$D$59,0)) | S30: =IF(Assumptions!$C$59="","",IFERROR(S26*Assumptions!$D$59,0)) | T30: =IF(Assumptions!$C$59="","",IFERROR(T26*Assumptions!$D$59,0)) | U30: =IF(Assumptions!$C$59="","",IFERROR(U26*Assumptions!$D$59,0)) | V30: =IF(Assumptions!$C$59="","",IFERROR(V26*Assumptions!$D$59,0)) | ... Z30: =IF(Assumptions!$C$59="","",IFERROR(Z26*Assumptions!$D$59,0)) | AA30: =SUM(O30:Z30) | AB30: =IF(Assumptions!$C$59="","",IFERROR(AB26*Assumptions!$D$59,0)) | AC30: =IF(Assumptions!$C$59="","",IFERROR(AC26*Assumptions!$D$59,0)) | AD30: =IF(Assumptions!$C$59="","",IFERROR(AD26*Assumptions!$D$59,0)) | AE30: =IF(Assumptions!$C$59="","",IFERROR(AE26*Assumptions!$D$59,0)) | AF30: =IF(Assumptions!$C$59="","",IFERROR(AF26*Assumptions!$D$59,0)) | AG30: =IF(Assumptions!$C$59="","",IFERROR(AG26*Assumptions!$D$59,0)) | AH30: =IF(Assumptions!$C$59="","",IFERROR(AH26*Assumptions!$D$59,0)) | AI30: =IF(Assumptions!$C$59="","",IFERROR(AI26*Assumptions!$D$59,0)) | ... AM30: =IF(Assumptions!$C$59="","",IFERROR(AM26*Assumptions!$D$59,0)) | AN30: =SUM(AB30:AM30) | AO30: =IF(Assumptions!$C$59="","",IFERROR(AO26*Assumptions!$D$59,0)) | AP30: =IF(Assumptions!$C$59="","",IFERROR(AP26*Assumptions!$D$59,0)) | AQ30: =IF(Assumptions!$C$59="","",IFERROR(AQ26*Assumptions!$D$59,0)) | AR30: =IF(Assumptions!$C$59="","",IFERROR(AR26*Assumptions!$D$59,0)) | AS30: =IF(Assumptions!$C$59="","",IFERROR(AS26*Assumptions!$D$59,0)) | AT30: =IF(Assumptions!$C$59="","",IFERROR(AT26*Assumptions!$D$59,0)) | AU30: =IF(Assumptions!$C$59="","",IFERROR(AU26*Assumptions!$D$59,0)) | AV30: =IF(Assumptions!$C$59="","",IFERROR(AV26*Assumptions!$D$59,0)) | ... AZ30: =IF(Assumptions!$C$59="","",IFERROR(AZ26*Assumptions!$D$59,0)) | BA30: =SUM(AO30:AZ30) | BB30: =IF(Assumptions!$C$59="","",IFERROR(BB26*Assumptions!$D$59,0)) | BC30: =IF(Assumptions!$C$59="","",IFERROR(BC26*Assumptions!$D$59,0)) | BD30: =IF(Assumptions!$C$59="","",IFERROR(BD26*Assumptions!$D$59,0)) | BE30: =IF(Assumptions!$C$59="","",IFERROR(BE26*Assumptions!$D$59,0)) | BF30: =IF(Assumptions!$C$59="","",IFERROR(BF26*Assumptions!$D$59,0)) | BG30: =IF(Assumptions!$C$59="","",IFERROR(BG26*Assumptions!$D$59,0)) | BH30: =IF(Assumptions!$C$59="","",IFERROR(BH26*Assumptions!$D$59,0)) | BI30: =IF(Assumptions!$C$59="","",IFERROR(BI26*Assumptions!$D$59,0)) | ... BM30: =IF(Assumptions!$C$59="","",IFERROR(BM26*Assumptions!$D$59,0)) | BN30: =SUM(BB30:BM30)
A31: =IF(Assumptions!$C$60="","",Assumptions!$C$60) | B31: =IF(Assumptions!$C$60="","",IFERROR(B26*Assumptions!$D$60,0)) | C31: =IF(Assumptions!$C$60="","",IFERROR(C26*Assumptions!$D$60,0)) | D31: =IF(Assumptions!$C$60="","",IFERROR(D26*Assumptions!$D$60,0)) | E31: =IF(Assumptions!$C$60="","",IFERROR(E26*Assumptions!$D$60,0)) | F31: =IF(Assumptions!$C$60="","",IFERROR(F26*Assumptions!$D$60,0)) | G31: =IF(Assumptions!$C$60="","",IFERROR(G26*Assumptions!$D$60,0)) | H31: =IF(Assumptions!$C$60="","",IFERROR(H26*Assumptions!$D$60,0)) | I31: =IF(Assumptions!$C$60="","",IFERROR(I26*Assumptions!$D$60,0)) | ... M31: =IF(Assumptions!$C$60="","",IFERROR(M26*Assumptions!$D$60,0)) | N31: =SUM(B31:M31) | O31: =IF(Assumptions!$C$60="","",IFERROR(O26*Assumptions!$D$60,0)) | P31: =IF(Assumptions!$C$60="","",IFERROR(P26*Assumptions!$D$60,0)) | Q31: =IF(Assumptions!$C$60="","",IFERROR(Q26*Assumptions!$D$60,0)) | R31: =IF(Assumptions!$C$60="","",IFERROR(R26*Assumptions!$D$60,0)) | S31: =IF(Assumptions!$C$60="","",IFERROR(S26*Assumptions!$D$60,0)) | T31: =IF(Assumptions!$C$60="","",IFERROR(T26*Assumptions!$D$60,0)) | U31: =IF(Assumptions!$C$60="","",IFERROR(U26*Assumptions!$D$60,0)) | V31: =IF(Assumptions!$C$60="","",IFERROR(V26*Assumptions!$D$60,0)) | ... Z31: =IF(Assumptions!$C$60="","",IFERROR(Z26*Assumptions!$D$60,0)) | AA31: =SUM(O31:Z31) | AB31: =IF(Assumptions!$C$60="","",IFERROR(AB26*Assumptions!$D$60,0)) | AC31: =IF(Assumptions!$C$60="","",IFERROR(AC26*Assumptions!$D$60,0)) | AD31: =IF(Assumptions!$C$60="","",IFERROR(AD26*Assumptions!$D$60,0)) | AE31: =IF(Assumptions!$C$60="","",IFERROR(AE26*Assumptions!$D$60,0)) | AF31: =IF(Assumptions!$C$60="","",IFERROR(AF26*Assumptions!$D$60,0)) | AG31: =IF(Assumptions!$C$60="","",IFERROR(AG26*Assumptions!$D$60,0)) | AH31: =IF(Assumptions!$C$60="","",IFERROR(AH26*Assumptions!$D$60,0)) | AI31: =IF(Assumptions!$C$60="","",IFERROR(AI26*Assumptions!$D$60,0)) | ... AM31: =IF(Assumptions!$C$60="","",IFERROR(AM26*Assumptions!$D$60,0)) | AN31: =SUM(AB31:AM31) | AO31: =IF(Assumptions!$C$60="","",IFERROR(AO26*Assumptions!$D$60,0)) | AP31: =IF(Assumptions!$C$60="","",IFERROR(AP26*Assumptions!$D$60,0)) | AQ31: =IF(Assumptions!$C$60="","",IFERROR(AQ26*Assumptions!$D$60,0)) | AR31: =IF(Assumptions!$C$60="","",IFERROR(AR26*Assumptions!$D$60,0)) | AS31: =IF(Assumptions!$C$60="","",IFERROR(AS26*Assumptions!$D$60,0)) | AT31: =IF(Assumptions!$C$60="","",IFERROR(AT26*Assumptions!$D$60,0)) | AU31: =IF(Assumptions!$C$60="","",IFERROR(AU26*Assumptions!$D$60,0)) | AV31: =IF(Assumptions!$C$60="","",IFERROR(AV26*Assumptions!$D$60,0)) | ... AZ31: =IF(Assumptions!$C$60="","",IFERROR(AZ26*Assumptions!$D$60,0)) | BA31: =SUM(AO31:AZ31) | BB31: =IF(Assumptions!$C$60="","",IFERROR(BB26*Assumptions!$D$60,0)) | BC31: =IF(Assumptions!$C$60="","",IFERROR(BC26*Assumptions!$D$60,0)) | BD31: =IF(Assumptions!$C$60="","",IFERROR(BD26*Assumptions!$D$60,0)) | BE31: =IF(Assumptions!$C$60="","",IFERROR(BE26*Assumptions!$D$60,0)) | BF31: =IF(Assumptions!$C$60="","",IFERROR(BF26*Assumptions!$D$60,0)) | BG31: =IF(Assumptions!$C$60="","",IFERROR(BG26*Assumptions!$D$60,0)) | BH31: =IF(Assumptions!$C$60="","",IFERROR(BH26*Assumptions!$D$60,0)) | BI31: =IF(Assumptions!$C$60="","",IFERROR(BI26*Assumptions!$D$60,0)) | ... BM31: =IF(Assumptions!$C$60="","",IFERROR(BM26*Assumptions!$D$60,0)) | BN31: =SUM(BB31:BM31)
A32: =IF(Assumptions!$C$61="","",Assumptions!$C$61) | B32: =IF(Assumptions!$C$61="","",IFERROR(B26*Assumptions!$D$61,0)) | C32: =IF(Assumptions!$C$61="","",IFERROR(C26*Assumptions!$D$61,0)) | D32: =IF(Assumptions!$C$61="","",IFERROR(D26*Assumptions!$D$61,0)) | E32: =IF(Assumptions!$C$61="","",IFERROR(E26*Assumptions!$D$61,0)) | F32: =IF(Assumptions!$C$61="","",IFERROR(F26*Assumptions!$D$61,0)) | G32: =IF(Assumptions!$C$61="","",IFERROR(G26*Assumptions!$D$61,0)) | H32: =IF(Assumptions!$C$61="","",IFERROR(H26*Assumptions!$D$61,0)) | I32: =IF(Assumptions!$C$61="","",IFERROR(I26*Assumptions!$D$61,0)) | ... M32: =IF(Assumptions!$C$61="","",IFERROR(M26*Assumptions!$D$61,0)) | N32: =SUM(B32:M32) | O32: =IF(Assumptions!$C$61="","",IFERROR(O26*Assumptions!$D$61,0)) | P32: =IF(Assumptions!$C$61="","",IFERROR(P26*Assumptions!$D$61,0)) | Q32: =IF(Assumptions!$C$61="","",IFERROR(Q26*Assumptions!$D$61,0)) | R32: =IF(Assumptions!$C$61="","",IFERROR(R26*Assumptions!$D$61,0)) | S32: =IF(Assumptions!$C$61="","",IFERROR(S26*Assumptions!$D$61,0)) | T32: =IF(Assumptions!$C$61="","",IFERROR(T26*Assumptions!$D$61,0)) | U32: =IF(Assumptions!$C$61="","",IFERROR(U26*Assumptions!$D$61,0)) | V32: =IF(Assumptions!$C$61="","",IFERROR(V26*Assumptions!$D$61,0)) | ... Z32: =IF(Assumptions!$C$61="","",IFERROR(Z26*Assumptions!$D$61,0)) | AA32: =SUM(O32:Z32) | AB32: =IF(Assumptions!$C$61="","",IFERROR(AB26*Assumptions!$D$61,0)) | AC32: =IF(Assumptions!$C$61="","",IFERROR(AC26*Assumptions!$D$61,0)) | AD32: =IF(Assumptions!$C$61="","",IFERROR(AD26*Assumptions!$D$61,0)) | AE32: =IF(Assumptions!$C$61="","",IFERROR(AE26*Assumptions!$D$61,0)) | AF32: =IF(Assumptions!$C$61="","",IFERROR(AF26*Assumptions!$D$61,0)) | AG32: =IF(Assumptions!$C$61="","",IFERROR(AG26*Assumptions!$D$61,0)) | AH32: =IF(Assumptions!$C$61="","",IFERROR(AH26*Assumptions!$D$61,0)) | AI32: =IF(Assumptions!$C$61="","",IFERROR(AI26*Assumptions!$D$61,0)) | ... AM32: =IF(Assumptions!$C$61="","",IFERROR(AM26*Assumptions!$D$61,0)) | AN32: =SUM(AB32:AM32) | AO32: =IF(Assumptions!$C$61="","",IFERROR(AO26*Assumptions!$D$61,0)) | AP32: =IF(Assumptions!$C$61="","",IFERROR(AP26*Assumptions!$D$61,0)) | AQ32: =IF(Assumptions!$C$61="","",IFERROR(AQ26*Assumptions!$D$61,0)) | AR32: =IF(Assumptions!$C$61="","",IFERROR(AR26*Assumptions!$D$61,0)) | AS32: =IF(Assumptions!$C$61="","",IFERROR(AS26*Assumptions!$D$61,0)) | AT32: =IF(Assumptions!$C$61="","",IFERROR(AT26*Assumptions!$D$61,0)) | AU32: =IF(Assumptions!$C$61="","",IFERROR(AU26*Assumptions!$D$61,0)) | AV32: =IF(Assumptions!$C$61="","",IFERROR(AV26*Assumptions!$D$61,0)) | ... AZ32: =IF(Assumptions!$C$61="","",IFERROR(AZ26*Assumptions!$D$61,0)) | BA32: =SUM(AO32:AZ32) | BB32: =IF(Assumptions!$C$61="","",IFERROR(BB26*Assumptions!$D$61,0)) | BC32: =IF(Assumptions!$C$61="","",IFERROR(BC26*Assumptions!$D$61,0)) | BD32: =IF(Assumptions!$C$61="","",IFERROR(BD26*Assumptions!$D$61,0)) | BE32: =IF(Assumptions!$C$61="","",IFERROR(BE26*Assumptions!$D$61,0)) | BF32: =IF(Assumptions!$C$61="","",IFERROR(BF26*Assumptions!$D$61,0)) | BG32: =IF(Assumptions!$C$61="","",IFERROR(BG26*Assumptions!$D$61,0)) | BH32: =IF(Assumptions!$C$61="","",IFERROR(BH26*Assumptions!$D$61,0)) | BI32: =IF(Assumptions!$C$61="","",IFERROR(BI26*Assumptions!$D$61,0)) | ... BM32: =IF(Assumptions!$C$61="","",IFERROR(BM26*Assumptions!$D$61,0)) | BN32: =SUM(BB32:BM32)
