Workbook

Sheet Cover
B4: CREDIT MONITORING ARRANGEMENT (CMA) & FINANCIAL FEASIBILITY REPORT
B9: ="Proposed "&Assumptions!$B$3&" Project" -> Proposed General Business Project
B11: ="Installed Capacity: __________ "&IFERROR(INDEX('Industry Labels'!$C$6:$Z$6,MATCH(Assumptions!$B$3,'Industry Labels'!$C$4:$Z$4,0)),"units/month")&" | Target Market: __________" -> Installed Capacity: __________ units/month | Target Market: __________
B13: PROJECT SNAPSHOT
B14: Project | D14: Project description (to be entered)
B15: Installed Capacity
B16: Location | D16: Location (to be entered)
B17: Constitution | D17: Constitution (e.g. Private Limited Company / LLP / Proprietorship)
B18: Total Project Cost
B19: Means of Finance
B20: Projection Horizon | D20: 5 Years × 12 Months = 60 Months (Monthly & Annual)
B21: Projected Start | D21: ="April "&IF(ISNUMBER(Assumptions!$B$6),Assumptions!$B$6,2026)&" (FY "&IF(ISNUMBER(Assumptions!$B$6),Assumptions!$B$6,2026)&"-"&RIGHT((IF(ISNUMBER(Assumptions!$B$6),Assumptions!$B$6,2026)+1),2)&" to FY "&(IF(ISNUMBER(Assumptions!$B$6),Assumptions!$B$6,2026)+4)&"-"&RIGHT((IF(ISNUMBER(Assumptions!$B$6),Assumptions!$B$6,2026)+5),2)&")" -> April 2026 (FY 2026-27 to FY 2030-31)
B22: Report Basis | D22: All figures in ₹ Lakh unless stated. BLANK TEMPLATE — enter inputs on the 'Assumptions' & 'Project Cost' sheets; all statements populate automatically.
B23: Prepared on
B25: DISCLAIMER: This projection is prepared for feasibility / bank appraisal (CMA) purposes. It is based on market data referenced in the 'Assumptions' sheet (live source links provided) and on stated assumptions which the promoter/appraiser must validate. Actual results will vary with market, utilisation and execution. Figures are indicative and do not constitute investment or lending advice.

Sheet Overview
A1: OVERVIEW — CMA FEASIBILITY MODEL (ALL INDUSTRIES)
A2: Industry-neutral greenfield project appraised in the Indian CMA / bank-appraisal format. Documentation only — links live to the model and changes nothing downstream.
A4: EXECUTIVE SUMMARY
A5: The project is a proposed new business unit, underwritten over a five-year horizon (60 months, all figures in ₹ Lakh). Value is created by commissioning the facility, equipment and support assets, then ramping capacity utilisation from a conservative Year-1 launch ramp to a sustainable ceiling by Year 5: installed capacity (Assumptions!B5) × the monthly utilisation ramp drives volume, which at an escalating realisation net of GST (Assumptions!B10) builds net sales, while direct cost (Assumptions!B11), utilities, consumables, labour and fixed overheads — each escalated year-on-year — convert that revenue into EBITDA, PAT and cash accruals. The capital stack funds the total project cost ('Project Cost'!C14) with promoter equity (Assumptions!B52) plus a bank term loan (Assumptions!B51), backed by a working-capital cash-credit line sized on the MPBF / Tandon 2nd-method assessment. The industry (Assumptions!B3) only changes labels and units, never the arithmetic.
A10: =IFERROR("Base-case headline returns — Average DSCR (Yrs 1-5): "&TEXT('Ratios & DSCR'!C26,"0.00")&"x • Year-5 EBITDA margin: "&TEXT('Ratios & DSCR'!G6,"0.0%")&" • Year-5 return on net worth: "&TEXT('Ratios & DSCR'!G10,"0.0%")&" (populate once inputs are entered).","Base-case headline returns — enter inputs on the 'Assumptions' sheet to populate DSCR, EBITDA margin and RoNW.") -> Base-case headline returns — Average DSCR (Yrs 1-5): 0.00x • Year-5 EBITDA margin: • Year-5 return on net worth: (populate once inputs are entered).
A12: AT A GLANCE
A13: Total project cost (₹ L) | B13: =IFERROR('Project Cost'!$C$14,"") -> 0 | D13: Debt : Equity (TL / Equity) | E13: =IFERROR(Assumptions!$B$51/Assumptions!$B$52,"")
A15: Net sales — Year 5 (₹ L) | B15: =IFERROR('Profitability (Annual)'!$G$9,"") -> 0 | D15: Average DSCR (Years 1-5) | E15: =IFERROR('Ratios & DSCR'!$C$26,"") -> 0
A17: All four figures are live links to the model, not typed numbers — they recalculate the moment inputs change. ₹ L = ₹ Lakh; a metric shows blank until its driver cells are filled in.
A19: HOW THE MODEL WORKS
A20: 1. Inputs live on 'Assumptions' (the single control panel).
A21: Every blue-font / yellow-fill cell in column B is a lever — capacity (B5), Year-1 price & material per unit (B10, B11), the 12-month utilisation ramp (B16:B27) and annual plateaus (B28:B31), escalations (B33:B37), cost drivers (B39:B49), financing (B51:B56), WC norms (B58:B62) and depreciation/tax (B64:B71). Nothing else should be typed.
A22: 2. 'Project Cost' fixes the capital stack.
A23: Cost of project (land, building, P&M, electricals, utilities, misc, contingency, pre-op, WC margin) totals in C14; means of finance pulls equity (=Assumptions!$B$52) and term loan (=Assumptions!$B$51) into C18:C19, and derives debt:equity (C22) and promoter contribution % (C23).
A24: 3. Linking mechanism — direct cross-sheet references.
A25: The model uses no named ranges; every sheet points straight at source cells with quoted sheet names — for example 'Profitability (Annual)'!$C$9 or Assumptions!$B$51. Each output is wrapped in IFERROR so a blank template shows clean empty cells rather than divide-by-zero errors while the inputs are still empty.
A26: 4. 'Depreciation' schedule (SLM, Companies Act Sch II).
A27: Takes the gross block from 'Project Cost' and the SLM rates from 'Assumptions' (B64:B69), producing the annual charge and closing net-fixed-asset book value (O13) and unamortised pre-op (O14) that feed the Balance Sheet.
A28: 5. 'Term Loan' repayment engine (60 months).
A29: Disburses the sanctioned loan, applies the principal moratorium (Assumptions!B54) then equal monthly principal over the repayment period (B55), and computes monthly interest at the term-loan rate (B53). Its opening/closing balances and interest feed the P&L, DSCR and Balance Sheet.
... A38: TIP — to re-underwrite: edit ONLY the blue / yellow input cells in column B of 'Assumptions' (and the cost lines in column C of 'Project Cost'). Every statement, ratio and the metrics above recalculate automatically; never overwrite a black formula cell.

Sheet Index
A1: INDEX / TABLE OF CONTENTS
A2: Click any row to jump to the sheet. The model is fully linked — change any blue input on 'Assumptions' and every sheet recalculates.
B4: # | C4: Sheet | D4: Description | E4: Go
C5: Cover | D5: Title page & project snapshot | E5: Open ↗
C6: Assumptions | D6: All inputs, blended price/cost engine & live data-source links | E6: Open ↗
C7: Project Cost | D7: Cost of project & means of finance (D:E) | E7: Open ↗
C8: Depreciation | D8: WDV depreciation & amortisation schedule | E8: Open ↗
C9: Term Loan | D9: Monthly term-loan repayment schedule (principal + interest) | E9: Open ↗
C10: Production & Sales | D10: 60-month volume plan: units × realisation → net sales | E10: Open ↗
C11: Profitability (Monthly) | D11: 60-month P&L — revenue to PAT, fully linked | E11: Open ↗
C12: Profitability (Annual) | D12: CMA Operating Statement (Form II) — 5-year roll-up | E12: Open ↗
C13: Working Capital | D13: Working-capital assessment & MPBF (Tandon II) | E13: Open ↗
C14: Balance Sheet | D14: Projected balance sheet (Form III) | E14: Open ↗
C15: Cash Flow | D15: Projected cash-flow statement (Form VI) + reconciliation | E15: Open ↗
C16: Ratios & DSCR | D16: Bankability ratios & debt-service coverage | E16: Open ↗
C17: Break-even & Sensitivity | D17: Break-even, margin of safety & sensitivity tables | E17: Open ↗
B19: KEY OUTPUTS AT A GLANCE
C20: Total project cost | E20: =IFERROR('Project Cost'!$C$14,"") -> 0
C21: Debt : Equity | E21: =IFERROR(Assumptions!$B$51/Assumptions!$B$52,"")
C22: Net sales – Year 1 | E22: =IFERROR('Profitability (Annual)'!$C$9,"") -> 0
C23: Net sales – Year 5 | E23: =IFERROR('Profitability (Annual)'!$G$9,"") -> 0
C24: EBITDA – Year 5 | E24: =IFERROR('Profitability (Annual)'!$G$27,"") -> 0
C25: PAT – Year 5 | E25: =IFERROR('Profitability (Annual)'!$G$36,"") -> 0
C26: Net worth – Year 5 | E26: =IFERROR('Balance Sheet'!$H$8,"") -> 0
C27: Average DSCR (Years 1-5) | E27: =IFERROR('Ratios & DSCR'!C26,"") -> 0

Sheet Assumptions
A1: ASSUMPTIONS & BASIS OF PROJECTIONS — full calculation engine (all downstream sheets link here)
A2: Blue = input you can change • Black = calculated • Yellow = key driver • Source column links are live (as at Jul-2026)
A3: Industry / business type | B3: General Business | C3: select | D3: Pick the business type — labels, units and notes across the whole model adapt. Calculations are identical for every industry.
A4: 1. GENERAL & TIMELINE
A5: =IFERROR(INDEX('Industry Labels'!$C$5:$Z$5,MATCH(Assumptions!$B$3,'Industry Labels'!$C$4:$Z$4,0)),"Installed / service capacity") -> Installed / service capacity | C5: =IFERROR(INDEX('Industry Labels'!$C$6:$Z$6,MATCH(Assumptions!$B$3,'Industry Labels'!$C$4:$Z$4,0)),"units/month") -> units/month | D5: Rated output at 100% utilisation; effective output is governed by the utilisation ramp (Section 3). Define one 'unit' clearly for your business.
A6: Commercial operations start (FY) | B6: 2026 | C6: year Yr1 starts | D6: Calendar year in which Year 1 starts (April). 2026 = FY2026-27. Every year / month heading in the model follows this.
A7: Working days / month (for WC norms) | C7: days | D7: Standard month convention for holding-period working-capital sizing.
A8: 2. UNIT ECONOMICS (PRICE & DIRECT MATERIAL, Year-1 base)
A9: Per-unit economics. Enter the selling price and direct cost from the promoter's own quotations / market survey — every downstream sheet recalculates automatically.
A10: =IFERROR(INDEX('Industry Labels'!$C$9:$Z$9,MATCH(Assumptions!$B$3,'Industry Labels'!$C$4:$Z$4,0)),"Average selling price / unit (Yr1)") -> Average selling price / unit (Yr1) | C10: ="₹/"&IFERROR(INDEX('Industry Labels'!$C$8:$Z$8,MATCH(Assumptions!$B$3,'Industry Labels'!$C$4:$Z$4,0)),"unit") -> ₹/unit | D10: Net-of-GST realisation per unit; escalated year-on-year by the price escalation (Section 4).
A11: =IFERROR(INDEX('Industry Labels'!$C$10:$Z$10,MATCH(Assumptions!$B$3,'Industry Labels'!$C$4:$Z$4,0)),"Direct cost of goods / services per unit (Yr1)") -> Direct cost of goods / services per unit (Yr1) | C11: ="₹/"&IFERROR(INDEX('Industry Labels'!$C$8:$Z$8,MATCH(Assumptions!$B$3,'Industry Labels'!$C$4:$Z$4,0)),"unit") -> ₹/unit | D11: Bought-in goods / direct cost of delivering one unit, inclusive of normal wastage.
A12: 3. CAPACITY UTILISATION (RAMP-UP)
A13: Year-1 monthly ramp (new facility / market development), then annual plateau. Conservative feasibility ramp.
A14: Year-1 utilisation, Months 1-12
A15: (month → util %)
A16: Year 1 – Month 1 | C16: % | D16: Commissioning / launch ramp-up
A17: Year 1 – Month 2 | C17: % | D17: Commissioning / launch ramp-up
A18: Year 1 – Month 3 | C18: % | D18: Commissioning / launch ramp-up
A19: Year 1 – Month 4 | C19: % | D19: Commissioning / launch ramp-up
A20: Year 1 – Month 5 | C20: % | D20: Commissioning / launch ramp-up
A21: Year 1 – Month 6 | C21: % | D21: Commissioning / launch ramp-up
A22: Year 1 – Month 7 | C22: % | D22: Stabilised ramp
A23: Year 1 – Month 8 | C23: % | D23: Stabilised ramp
A24: Year 1 – Month 9 | C24: % | D24: Stabilised ramp
A25: Year 1 – Month 10 | C25: % | D25: Stabilised ramp
A26: Year 1 – Month 11 | C26: % | D26: Stabilised ramp
A27: Year 1 – Month 12 | C27: % | D27: Stabilised ramp
... A31: Year 5 utilisation | C31: % | D31: Sustainable ceiling (allows maintenance downtime).
A32: 4. ANNUAL ESCALATION (applied Year-on-Year)
A33: Selling-price escalation | C33: % p.a. | D33: Realisation growth broadly tracking input inflation.
A34: Direct-material escalation | C34: % p.a. | D34: Expected annual input-material price trend.
A35: Utility / power tariff escalation | C35: % p.a. | D35: Annual drift in utility tariffs.
A36: Wage / salary escalation | C36: % p.a. | D36: Annual increments + statutory revisions.
A37: Other overhead escalation | C37: % p.a. | D37: General inflation on fixed overheads.
A38: 5. OTHER VARIABLE COST DRIVERS (Year-1 base)
A39: =IFERROR(INDEX('Industry Labels'!$C$11:$Z$11,MATCH(Assumptions!$B$3,'Industry Labels'!$C$4:$Z$4,0)),"Utilities & energy / unit") -> Utilities & energy / unit | C39: ="₹/"&IFERROR(INDEX('Industry Labels'!$C$8:$Z$8,MATCH(Assumptions!$B$3,'Industry Labels'!$C$4:$Z$4,0)),"unit") -> ₹/unit | D39: Energy / utilities cost per unit; escalates with the utility-cost escalation (Section 4).
A40: =IFERROR(INDEX('Industry Labels'!$C$12:$Z$12,MATCH(Assumptions!$B$3,'Industry Labels'!$C$4:$Z$4,0)),"Consumables & supplies / unit") -> Consumables & supplies / unit | C40: ="₹/"&IFERROR(INDEX('Industry Labels'!$C$8:$Z$8,MATCH(Assumptions!$B$3,'Industry Labels'!$C$4:$Z$4,0)),"unit") -> ₹/unit | D40: Consumable supplies consumed per unit.
A41: =IFERROR(INDEX('Industry Labels'!$C$13:$Z$13,MATCH(Assumptions!$B$3,'Industry Labels'!$C$4:$Z$4,0)),"Packing & delivery / unit") -> Packing & delivery / unit | C41: ="₹/"&IFERROR(INDEX('Industry Labels'!$C$8:$Z$8,MATCH(Assumptions!$B$3,'Industry Labels'!$C$4:$Z$4,0)),"unit") -> ₹/unit | D41: Packing / delivery / distribution cost per unit.
A42: =IFERROR(INDEX('Industry Labels'!$C$14:$Z$14,MATCH(Assumptions!$B$3,'Industry Labels'!$C$4:$Z$4,0)),"Direct labour (Year-1)") -> Direct labour (Year-1) | C42: ₹L/mo | D42: Operating staff across shifts; semi-fixed, escalates with wages.
A43: 6. FIXED / OVERHEAD COSTS (Year-1 base, monthly)
...

Sheet Project Cost
A1: PROJECT COST & MEANS OF FINANCE (₹ Lakh)
A3: A. COST OF PROJECT
A4: # | B4: Particulars | C4: Amount | D4: Dep. block | E4: Basis / remarks
B5: Land & site development | D5: Land (nil dep.) | E5: Land / site / premises development (enter nil if premises are leased).
B6: =IFERROR(INDEX('Industry Labels'!$C$15:$Z$15,MATCH(Assumptions!$B$3,'Industry Labels'!$C$4:$Z$4,0)),"Premises, building & civil / fit-out") -> Premises, building & civil / fit-out | D6: Building | E6: Construction / civil works / interiors & fit-out of premises.
B7: =IFERROR(INDEX('Industry Labels'!$C$16:$Z$16,MATCH(Assumptions!$B$3,'Industry Labels'!$C$4:$Z$4,0)),"Equipment, machinery & systems") -> Equipment, machinery & systems | D7: Equipment | E7: Core equipment, machinery, vehicles or systems & installation.
B8: Electrical installation & power back-up | D8: Electrical | E8: Panels, wiring, transformer, DG / UPS back-up.
B9: Utilities & services (water, HVAC, fire-fighting etc.) | D9: Utilities | E9: Water, cooling / air-conditioning, fire-fighting, other services.
B10: Miscellaneous fixed assets (office, IT, furniture, tools) | D10: Misc | E10: Furniture, computers, software / ERP, tools, testing equipment.
B11: Contingency | D11: Equipment | E11: ~3% on equipment / civil for cost overrun.
B12: Pre-operative & preliminary expenses | D12: Pre-op (amort.) | E12: Trial runs, interest during construction, fees, start-up and licensing costs.
B13: Margin money for working capital | D13: Current assets | E13: Promoter margin toward the first working-capital cycle.
B14: TOTAL PROJECT COST | C14: =IFERROR(SUM(C5:C13),"") -> 0
A16: B. MEANS OF FINANCE
A17: # | B17: Source | C17: Amount | D17: % of cost | E17: Remarks
B18: Promoter's equity / capital | C18: =IFERROR(Assumptions!$B$52,"") -> 0 | D18: =IFERROR(C18/$C$14,"") | E18: Incl. WC margin money.
B19: Term loan from bank | C19: =IFERROR(Assumptions!$B$51,"") -> 0 | D19: =IFERROR(C19/$C$14,"") | E19: Secured against fixed assets.
B20: TOTAL MEANS OF FINANCE | C20: =IFERROR(SUM(C18:C19),"") -> 0 | D20: =IFERROR(C20/$C$14,"")
B21: Check (Cost = Finance) | C21: =IFERROR(C14-C20,"") -> 0
B22: Debt : Equity (Term loan / Equity) | C22: =IFERROR(Assumptions!$B$51/Assumptions!$B$52,"")
B23: Promoter contribution % | C23: =IFERROR(Assumptions!$B$52/C14,"")

Sheet Depreciation
A1: DEPRECIATION SCHEDULE — Straight-Line Method, Companies Act Schedule II (₹ Lakh)
A2: Gross block from 'Project Cost'; SLM rates (per asset useful life) from 'Assumptions'. Gross block × SLM rate = annual charge, floored at residual book value.
D3: Year 1 | G3: Year 2 | J3: Year 3 | M3: Year 4 | P3: Year 5
A4: Asset block | B4: Gross | C4: Rate | D4: Open | E4: Dep. | F4: Close | G4: Open | H4: Dep. | I4: Close | J4: Open | K4: Dep. | L4: Close | M4: Open | N4: Dep. | O4: Close | P4: Open | Q4: Dep. | R4: Close
A5: =IFERROR(INDEX('Industry Labels'!$C$15:$Z$15,MATCH(Assumptions!$B$3,'Industry Labels'!$C$4:$Z$4,0)),"Premises, building & civil / fit-out") -> Premises, building & civil / fit-out | B5: =IFERROR('Project Cost'!$C$6,"") -> 0 | C5: =IFERROR(Assumptions!$B$64,"") -> 0 | D5: =IFERROR(B5,"") -> 0 | E5: =IFERROR(MIN(D5,$B5*$C5),"") -> 0 | F5: =IFERROR(D5-E5,"") -> 0 | G5: =IFERROR(F5,"") -> 0 | H5: =IFERROR(MIN(G5,$B5*$C5),"") -> 0 | I5: =IFERROR(G5-H5,"") -> 0 | J5: =IFERROR(I5,"") -> 0 | K5: =IFERROR(MIN(J5,$B5*$C5),"") -> 0 | L5: =IFERROR(J5-K5,"") -> 0 | M5: =IFERROR(L5,"") -> 0 | N5: =IFERROR(MIN(M5,$B5*$C5),"") -> 0 | O5: =IFERROR(M5-N5,"") -> 0 | P5: =IFERROR(O5,"") -> 0 | Q5: =IFERROR(MIN(P5,$B5*$C5),"") -> 0 | R5: =IFERROR(P5-Q5,"") -> 0
A6: =IFERROR(INDEX('Industry Labels'!$C$16:$Z$16,MATCH(Assumptions!$B$3,'Industry Labels'!$C$4:$Z$4,0)),"Equipment, machinery & systems")&" (+contingency)" -> Equipment, machinery & systems (+contingency) | B6: =IFERROR(('Project Cost'!$C$7+'Project Cost'!$C$11),"") -> 0 | C6: =IFERROR(Assumptions!$B$65,"") -> 0 | D6: =IFERROR(B6,"") -> 0 | E6: =IFERROR(MIN(D6,$B6*$C6),"") -> 0 | F6: =IFERROR(D6-E6,"") -> 0 | G6: =IFERROR(F6,"") -> 0 | H6: =IFERROR(MIN(G6,$B6*$C6),"") -> 0 | I6: =IFERROR(G6-H6,"") -> 0 | J6: =IFERROR(I6,"") -> 0 | K6: =IFERROR(MIN(J6,$B6*$C6),"") -> 0 | L6: =IFERROR(J6-K6,"") -> 0 | M6: =IFERROR(L6,"") -> 0 | N6: =IFERROR(MIN(M6,$B6*$C6),"") -> 0 | O6: =IFERROR(M6-N6,"") -> 0 | P6: =IFERROR(O6,"") -> 0 | Q6: =IFERROR(MIN(P6,$B6*$C6),"") -> 0 | R6: =IFERROR(P6-Q6,"") -> 0
A7: Electrical installation | B7: =IFERROR('Project Cost'!$C$8,"") -> 0 | C7: =IFERROR(Assumptions!$B$66,"") -> 0 | D7: =IFERROR(B7,"") -> 0 | E7: =IFERROR(MIN(D7,$B7*$C7),"") -> 0 | F7: =IFERROR(D7-E7,"") -> 0 | G7: =IFERROR(F7,"") -> 0 | H7: =IFERROR(MIN(G7,$B7*$C7),"") -> 0 | I7: =IFERROR(G7-H7,"") -> 0 | J7: =IFERROR(I7,"") -> 0 | K7: =IFERROR(MIN(J7,$B7*$C7),"") -> 0 | L7: =IFERROR(J7-K7,"") -> 0 | M7: =IFERROR(L7,"") -> 0 | N7: =IFERROR(MIN(M7,$B7*$C7),"") -> 0 | O7: =IFERROR(M7-N7,"") -> 0 | P7: =IFERROR(O7,"") -> 0 | Q7: =IFERROR(MIN(P7,$B7*$C7),"") -> 0 | R7: =IFERROR(P7-Q7,"") -> 0
A8: Utilities | B8: =IFERROR('Project Cost'!$C$9,"") -> 0 | C8: =IFERROR(Assumptions!$B$67,"") -> 0 | D8: =IFERROR(B8,"") -> 0 | E8: =IFERROR(MIN(D8,$B8*$C8),"") -> 0 | F8: =IFERROR(D8-E8,"") -> 0 | G8: =IFERROR(F8,"") -> 0 | H8: =IFERROR(MIN(G8,$B8*$C8),"") -> 0 | I8: =IFERROR(G8-H8,"") -> 0 | J8: =IFERROR(I8,"") -> 0 | K8: =IFERROR(MIN(J8,$B8*$C8),"") -> 0 | L8: =IFERROR(J8-K8,"") -> 0 | M8: =IFERROR(L8,"") -> 0 | N8: =IFERROR(MIN(M8,$B8*$C8),"") -> 0 | O8: =IFERROR(M8-N8,"") -> 0 | P8: =IFERROR(O8,"") -> 0 | Q8: =IFERROR(MIN(P8,$B8*$C8),"") -> 0 | R8: =IFERROR(P8-Q8,"") -> 0
A9: Miscellaneous / office assets | B9: =IFERROR('Project Cost'!$C$10,"") -> 0 | C9: =IFERROR(Assumptions!$B$68,"") -> 0 | D9: =IFERROR(B9,"") -> 0 | E9: =IFERROR(MIN(D9,$B9*$C9),"") -> 0 | F9: =IFERROR(D9-E9,"") -> 0 | G9: =IFERROR(F9,"") -> 0 | H9: =IFERROR(MIN(G9,$B9*$C9),"") -> 0 | I9: =IFERROR(G9-H9,"") -> 0 | J9: =IFERROR(I9,"") -> 0 | K9: =IFERROR(MIN(J9,$B9*$C9),"") -> 0 | L9: =IFERROR(J9-K9,"") -> 0 | M9: =IFERROR(L9,"") -> 0 | N9: =IFERROR(MIN(M9,$B9*$C9),"") -> 0 | O9: =IFERROR(M9-N9,"") -> 0 | P9: =IFERROR(O9,"") -> 0 | Q9: =IFERROR(MIN(P9,$B9*$C9),"") -> 0 | R9: =IFERROR(P9-Q9,"") -> 0
A10: Pre-operative (amortised 5 yr SL) | B10: =IFERROR('Project Cost'!$C$12,"") -> 0 | C10: =IFERROR(Assumptions!$B$69,"") -> 0 | D10: =IFERROR(B10,"") -> 0 | E10: =IFERROR(MIN(D10,$B10*$C10),"") -> 0 | F10: =IFERROR(D10-E10,"") -> 0 | G10: =IFERROR(F10,"") -> 0 | H10: =IFERROR(MIN(G10,$B10*$C10),"") -> 0 | I10: =IFERROR(G10-H10,"") -> 0 | J10: =IFERROR(I10,"") -> 0 | K10: =IFERROR(MIN(J10,$B10*$C10),"") -> 0 | L10: =IFERROR(J10-K10,"") -> 0 | M10: =IFERROR(L10,"") -> 0 | N10: =IFERROR(MIN(M10,$B10*$C10),"") -> 0 | O10: =IFERROR(M10-N10,"") -> 0 | P10: =IFERROR(O10,"") -> 0 | Q10: =IFERROR(MIN(P10,$B10*$C10),"") -> 0 | R10: =IFERROR(P10-Q10,"") -> 0
A11: TOTAL DEPRECIATION & AMORTISATION | E11: =IFERROR(SUM(E5:E10),"") -> 0 | H11: =IFERROR(SUM(H5:H10),"") -> 0 | K11: =IFERROR(SUM(K5:K10),"") -> 0 | N11: =IFERROR(SUM(N5:N10),"") -> 0 | Q11: =IFERROR(SUM(Q5:Q10),"") -> 0
A13: Net fixed assets (closing book value incl. land, excl. pre-op) | F13: =IFERROR(SUM(F5:F9)+'Project Cost'!$C$5,"") -> 0 | I13: =IFERROR(SUM(I5:I9)+'Project Cost'!$C$5,"") -> 0 | L13: =IFERROR(SUM(L5:L9)+'Project Cost'!$C$5,"") -> 0 | O13: =IFERROR(SUM(O5:O9)+'Project Cost'!$C$5,"") -> 0 | R13: =IFERROR(SUM(R5:R9)+'Project Cost'!$C$5,"") -> 0
A14: Pre-operative (unamortised, closing) | F14: =IFERROR(F10,"") -> 0 | I14: =IFERROR(I10,"") -> 0 | L14: =IFERROR(L10,"") -> 0 | O14: =IFERROR(O10,"") -> 0 | R14: =IFERROR(R10,"") -> 0

Sheet Term Loan
A1: TERM LOAN REPAYMENT SCHEDULE (₹ Lakh)
A2: Disbursed at start. Moratorium on principal per Assumptions; interest serviced monthly. Repaid in equal monthly principal thereafter.
C3: ="YEAR 1 • FY"&(IF(ISNUMBER(Assumptions!$B$6),Assumptions!$B$6,2026)+0)&"-"&RIGHT((IF(ISNUMBER(Assumptions!$B$6),Assumptions!$B$6,2026)+0+1),2) -> YEAR 1 • FY2026-27 | O3: ="YEAR 2 • FY"&(IF(ISNUMBER(Assumptions!$B$6),Assumptions!$B$6,2026)+1)&"-"&RIGHT((IF(ISNUMBER(Assumptions!$B$6),Assumptions!$B$6,2026)+1+1),2) -> YEAR 2 • FY2027-28 | AA3: ="YEAR 3 • FY"&(IF(ISNUMBER(Assumptions!$B$6),Assumptions!$B$6,2026)+2)&"-"&RIGHT((IF(ISNUMBER(Assumptions!$B$6),Assumptions!$B$6,2026)+2+1),2) -> YEAR 3 • FY2028-29 | AM3: ="YEAR 4 • FY"&(IF(ISNUMBER(Assumptions!$B$6),Assumptions!$B$6,2026)+3)&"-"&RIGHT((IF(ISNUMBER(Assumptions!$B$6),Assumptions!$B$6,2026)+3+1),2) -> YEAR 4 • FY2029-30 | AY3: ="YEAR 5 • FY"&(IF(ISNUMBER(Assumptions!$B$6),Assumptions!$B$6,2026)+4)&"-"&RIGHT((IF(ISNUMBER(Assumptions!$B$6),Assumptions!$B$6,2026)+4+1),2) -> YEAR 5 • FY2030-31
A4: Month | B4: Unit | C4: =DATE(IF(ISNUMBER(Assumptions!$B$6),Assumptions!$B$6,2026),4+0,1) -> 46113 | D4: =DATE(IF(ISNUMBER(Assumptions!$B$6),Assumptions!$B$6,2026),4+1,1) -> 46143 | E4: =DATE(IF(ISNUMBER(Assumptions!$B$6),Assumptions!$B$6,2026),4+2,1) -> 46174 | F4: =DATE(IF(ISNUMBER(Assumptions!$B$6),Assumptions!$B$6,2026),4+3,1) -> 46204 | G4: =DATE(IF(ISNUMBER(Assumptions!$B$6),Assumptions!$B$6,2026),4+4,1) -> 46235 | H4: =DATE(IF(ISNUMBER(Assumptions!$B$6),Assumptions!$B$6,2026),4+5,1) -> 46266 | I4: =DATE(IF(ISNUMBER(Assumptions!$B$6),Assumptions!$B$6,2026),4+6,1) -> 46296 | J4: =DATE(IF(ISNUMBER(Assumptions!$B$6),Assumptions!$B$6,2026),4+7,1) -> 46327 | K4: =DATE(IF(ISNUMBER(Assumptions!$B$6),Assumptions!$B$6,2026),4+8,1) -> 46357 | L4: =DATE(IF(ISNUMBER(Assumptions!$B$6),Assumptions!$B$6,2026),4+9,1) -> 46388 | M4: =DATE(IF(ISNUMBER(Assumptions!$B$6),Assumptions!$B$6,2026),4+10,1) -> 46419 | N4: =DATE(IF(ISNUMBER(Assumptions!$B$6),Assumptions!$B$6,2026),4+11,1) -> 46447 | O4: =DATE(IF(ISNUMBER(Assumptions!$B$6),Assumptions!$B$6,2026),4+12,1) -> 46478 | P4: =DATE(IF(ISNUMBER(Assumptions!$B$6),Assumptions!$B$6,2026),4+13,1) -> 46508 | Q4: =DATE(IF(ISNUMBER(Assumptions!$B$6),Assumptions!$B$6,2026),4+14,1) -> 46539 | R4: =DATE(IF(ISNUMBER(Assumptions!$B$6),Assumptions!$B$6,2026),4+15,1) -> 46569 | S4: =DATE(IF(ISNUMBER(Assumptions!$B$6),Assumptions!$B$6,2026),4+16,1) -> 46600 | T4: =DATE(IF(ISNUMBER(Assumptions!$B$6),Assumptions!$B$6,2026),4+17,1) -> 46631 | U4: =DATE(IF(ISNUMBER(Assumptions!$B$6),Assumptions!$B$6,2026),4+18,1) -> 46661 | V4: =DATE(IF(ISNUMBER(Assumptions!$B$6),Assumptions!$B$6,2026),4+19,1) -> 46692 | W4: =DATE(IF(ISNUMBER(Assumptions!$B$6),Assumptions!$B$6,2026),4+20,1) -> 46722 | X4: =DATE(IF(ISNUMBER(Assumptions!$B$6),Assumptions!$B$6,2026),4+21,1) -> 46753 | Y4: =DATE(IF(ISNUMBER(Assumptions!$B$6),Assumptions!$B$6,2026),4+22,1) -> 46784 | Z4: =DATE(IF(ISNUMBER(Assumptions!$B$6),Assumptions!$B$6,2026),4+23,1) -> 46813 | AA4: =DATE(IF(ISNUMBER(Assumptions!$B$6),Assumptions!$B$6,2026),4+24,1) -> 46844 | AB4: =DATE(IF(ISNUMBER(Assumptions!$B$6),Assumptions!$B$6,2026),4+25,1) -> 46874 | AC4: =DATE(IF(ISNUMBER(Assumptions!$B$6),Assumptions!$B$6,2026),4+26,1) -> 46905 | AD4: =DATE(IF(ISNUMBER(Assumptions!$B$6),Assumptions!$B$6,2026),4+27,1) -> 46935 | AE4: =DATE(IF(ISNUMBER(Assumptions!$B$6),Assumptions!$B$6,2026),4+28,1) -> 46966 | AF4: =DATE(IF(ISNUMBER(Assumptions!$B$6),Assumptions!$B$6,2026),4+29,1) -> 46997 | AG4: =DATE(IF(ISNUMBER(Assumptions!$B$6),Assumptions!$B$6,2026),4+30,1) -> 47027 | AH4: =DATE(IF(ISNUMBER(Assumptions!$B$6),Assumptions!$B$6,2026),4+31,1) -> 47058 | AI4: =DATE(IF(ISNUMBER(Assumptions!$B$6),Assumptions!$B$6,2026),4+32,1) -> 47088 | AJ4: =DATE(IF(ISNUMBER(Assumptions!$B$6),Assumptions!$B$6,2026),4+33,1) -> 47119 | AK4: =DATE(IF(ISNUMBER(Assumptions!$B$6),Assumptions!$B$6,2026),4+34,1) -> 47150 | AL4: =DATE(IF(ISNUMBER(Assumptions!$B$6),Assumptions!$B$6,2026),4+35,1) -> 47178 | AM4: =DATE(IF(ISNUMBER(Assumptions!$B$6),Assumptions!$B$6,2026),4+36,1) -> 47209 | AN4: =DATE(IF(ISNUMBER(Assumptions!$B$6),Assumptions!$B$6,2026),4+37,1) -> 47239 | AO4: =DATE(IF(ISNUMBER(Assumptions!$B$6),Assumptions!$B$6,2026),4+38,1) -> 47270 | AP4: =DATE(IF(ISNUMBER(Assumptions!$B$6),Assumptions!$B$6,2026),4+39,1) -> 47300 | AQ4: =DATE(IF(ISNUMBER(Assumptions!$B$6),Assumptions!$B$6,2026),4+40,1) -> 47331 | AR4: =DATE(IF(ISNUMBER(Assumptions!$B$6),Assumptions!$B$6,2026),4+41,1) -> 47362 | AS4: =DATE(IF(ISNUMBER(Assumptions!$B$6),Assumptions!$B$6,2026),4+42,1) -> 47392 | AT4: =DATE(IF(ISNUMBER(Assumptions!$B$6),Assumptions!$B$6,2026),4+43,1) -> 47423 | AU4: =DATE(IF(ISNUMBER(Assumptions!$B$6),Assumptions!$B$6,2026),4+44,1) -> 47453 | AV4: =DATE(IF(ISNUMBER(Assumptions!$B$6),Assumptions!$B$6,2026),4+45,1) -> 47484 | AW4: =DATE(IF(ISNUMBER(Assumptions!$B$6),Assumptions!$B$6,2026),4+46,1) -> 47515 | AX4: =DATE(IF(ISNUMBER(Assumptions!$B$6),Assumptions!$B$6,2026),4+47,1) -> 47543 | AY4: =DATE(IF(ISNUMBER(Assumptions!$B$6),Assumptions!$B$6,2026),4+48,1) -> 47574 | AZ4: =DATE(IF(ISNUMBER(Assumptions!$B$6),Assumptions!$B$6,2026),4+49,1) -> 47604 | BA4: =DATE(IF(ISNUMBER(Assumptions!$B$6),Assumptions!$B$6,2026),4+50,1) -> 47635 | BB4: =DATE(IF(ISNUMBER(Assumptions!$B$6),Assumptions!$B$6,2026),4+51,1) -> 47665 | BC4: =DATE(IF(ISNUMBER(Assumptions!$B$6),Assumptions!$B$6,2026),4+52,1) -> 47696 | BD4: =DATE(IF(ISNUMBER(Assumptions!$B$6),Assumptions!$B$6,2026),4+53,1) -> 47727 | BE4: =DATE(IF(ISNUMBER(Assumptions!$B$6),Assumptions!$B$6,2026),4+54,1) -> 47757 | BF4: =DATE(IF(ISNUMBER(Assumptions!$B$6),Assumptions!$B$6,2026),4+55,1) -> 47788 | BG4: =DATE(IF(ISNUMBER(Assumptions!$B$6),Assumptions!$B$6,2026),4+56,1) -> 47818 | BH4: =DATE(IF(ISNUMBER(Assumptions!$B$6),Assumptions!$B$6,2026),4+57,1) -> 47849 | BI4: =DATE(IF(ISNUMBER(Assumptions!$B$6),Assumptions!$B$6,2026),4+58,1) -> 47880 | BJ4: =DATE(IF(ISNUMBER(Assumptions!$B$6),Assumptions!$B$6,2026),4+59,1) -> 47908
A5: Month # | C5: 1 | D5: 2 | E5: 3 | F5: 4 | G5: 5 | H5: 6 | I5: 7 | J5: 8 | K5: 9 | L5: 10 | M5: 11 | N5: 12 | O5: 13 | P5: 14 | Q5: 15 | R5: 16 | S5: 17 | T5: 18 | U5: 19 | V5: 20 | W5: 21 | X5: 22 | Y5: 23 | Z5: 24 | AA5: 25 | AB5: 26 | AC5: 27 | AD5: 28 | AE5: 29 | AF5: 30 | AG5: 31 | AH5: 32 | AI5: 33 | AJ5: 34 | AK5: 35 | AL5: 36 | AM5: 37 | AN5: 38 | AO5: 39 | AP5: 40 | AQ5: 41 | AR5: 42 | AS5: 43 | AT5: 44 | AU5: 45 | AV5: 46 | AW5: 47 | AX5: 48 | AY5: 49 | AZ5: 50 | BA5: 51 | BB5: 52 | BC5: 53 | BD5: 54 | BE5: 55 | BF5: 56 | BG5: 57 | BH5: 58 | BI5: 59 | BJ5: 60
A6: Year # | C6: 1 | D6: 1 | E6: 1 | F6: 1 | G6: 1 | H6: 1 | I6: 1 | J6: 1 | K6: 1 | L6: 1 | M6: 1 | N6: 1 | O6: 2 | P6: 2 | Q6: 2 | R6: 2 | S6: 2 | T6: 2 | U6: 2 | V6: 2 | W6: 2 | X6: 2 | Y6: 2 | Z6: 2 | AA6: 3 | AB6: 3 | AC6: 3 | AD6: 3 | AE6: 3 | AF6: 3 | AG6: 3 | AH6: 3 | AI6: 3 | AJ6: 3 | AK6: 3 | AL6: 3 | AM6: 4 | AN6: 4 | AO6: 4 | AP6: 4 | AQ6: 4 | AR6: 4 | AS6: 4 | AT6: 4 | AU6: 4 | AV6: 4 | AW6: 4 | AX6: 4 | AY6: 5 | AZ6: 5 | BA6: 5 | BB6: 5 | BC6: 5 | BD6: 5 | BE6: 5 | BF6: 5 | BG6: 5 | BH6: 5 | BI6: 5 | BJ6: 5
A7: Opening loan balance | B7: ₹ L | C7: =IFERROR(Assumptions!$B$51,"") -> 0 | D7: =IFERROR(C11,"") -> 0 | E7: =IFERROR(D11,"") -> 0 | F7: =IFERROR(E11,"") -> 0 | G7: =IFERROR(F11,"") -> 0 | H7: =IFERROR(G11,"") -> 0 | I7: =IFERROR(H11,"") -> 0 | J7: =IFERROR(I11,"") -> 0 | K7: =IFERROR(J11,"") -> 0 | ... BJ7: =IFERROR(BI11,"") -> 0
A8: Add: disbursement | B8: ₹ L
A9: Less: principal repayment | B9: ₹ L | C9: =IFERROR(IF(AND(C5>Assumptions!$B$54,C5<=Assumptions!$B$54+Assumptions!$B$55),Assumptions!$B$51/Assumptions!$B$55,0),"") -> 0 | D9: =IFERROR(IF(AND(D5>Assumptions!$B$54,D5<=Assumptions!$B$54+Assumptions!$B$55),Assumptions!$B$51/Assumptions!$B$55,0),"") -> 0 | E9: =IFERROR(IF(AND(E5>Assumptions!$B$54,E5<=Assumptions!$B$54+Assumptions!$B$55),Assumptions!$B$51/Assumptions!$B$55,0),"") -> 0 | F9: =IFERROR(IF(AND(F5>Assumptions!$B$54,F5<=Assumptions!$B$54+Assumptions!$B$55),Assumptions!$B$51/Assumptions!$B$55,0),"") -> 0 | G9: =IFERROR(IF(AND(G5>Assumptions!$B$54,G5<=Assumptions!$B$54+Assumptions!$B$55),Assumptions!$B$51/Assumptions!$B$55,0),"") -> 0 | H9: =IFERROR(IF(AND(H5>Assumptions!$B$54,H5<=Assumptions!$B$54+Assumptions!$B$55),Assumptions!$B$51/Assumptions!$B$55,0),"") -> 0 | I9: =IFERROR(IF(AND(I5>Assumptions!$B$54,I5<=Assumptions!$B$54+Assumptions!$B$55),Assumptions!$B$51/Assumptions!$B$55,0),"") -> 0 | J9: =IFERROR(IF(AND(J5>Assumptions!$B$54,J5<=Assumptions!$B$54+Assumptions!$B$55),Assumptions!$B$51/Assumptions!$B$55,0),"") -> 0 | ... BJ9: =IFERROR(IF(AND(BJ5>Assumptions!$B$54,BJ5<=Assumptions!$B$54+Assumptions!$B$55),Assumptions!$B$51/Assumptions!$B$55,0),"") -> 0
A10: Interest for the month | B10: ₹ L | C10: =IFERROR(C7*Assumptions!$B$53/12,"") -> 0 | D10: =IFERROR(D7*Assumptions!$B$53/12,"") -> 0 | E10: =IFERROR(E7*Assumptions!$B$53/12,"") -> 0 | F10: =IFERROR(F7*Assumptions!$B$53/12,"") -> 0 | G10: =IFERROR(G7*Assumptions!$B$53/12,"") -> 0 | H10: =IFERROR(H7*Assumptions!$B$53/12,"") -> 0 | I10: =IFERROR(I7*Assumptions!$B$53/12,"") -> 0 | J10: =IFERROR(J7*Assumptions!$B$53/12,"") -> 0 | ... BJ10: =IFERROR(BJ7*Assumptions!$B$53/12,"") -> 0
A11: Closing loan balance | B11: ₹ L | C11: =IFERROR(C7+C8-C9,"") -> 0 | D11: =IFERROR(D7+D8-D9,"") -> 0 | E11: =IFERROR(E7+E8-E9,"") -> 0 | F11: =IFERROR(F7+F8-F9,"") -> 0 | G11: =IFERROR(G7+G8-G9,"") -> 0 | H11: =IFERROR(H7+H8-H9,"") -> 0 | I11: =IFERROR(I7+I8-I9,"") -> 0 | J11: =IFERROR(J7+J8-J9,"") -> 0 | ... BJ11: =IFERROR(BJ7+BJ8-BJ9,"") -> 0
A12: Total outflow (principal + interest) | B12: ₹ L | C12: =IFERROR(C9+C10,"") -> 0 | D12: =IFERROR(D9+D10,"") -> 0 | E12: =IFERROR(E9+E10,"") -> 0 | F12: =IFERROR(F9+F10,"") -> 0 | G12: =IFERROR(G9+G10,"") -> 0 | H12: =IFERROR(H9+H10,"") -> 0 | I12: =IFERROR(I9+I10,"") -> 0 | J12: =IFERROR(J9+J10,"") -> 0 | ... BJ12: =IFERROR(BJ9+BJ10,"") -> 0

Sheet Production & Sales
A1: OUTPUT / VOLUME & SALES PLAN (monthly, 5 years)
A2: Capacity × utilisation = units delivered; units × escalated realisation = net sales (₹ Lakh).
C3: ="YEAR 1 • FY"&(IF(ISNUMBER(Assumptions!$B$6),Assumptions!$B$6,2026)+0)&"-"&RIGHT((IF(ISNUMBER(Assumptions!$B$6),Assumptions!$B$6,2026)+0+1),2) -> YEAR 1 • FY2026-27 | O3: ="YEAR 2 • FY"&(IF(ISNUMBER(Assumptions!$B$6),Assumptions!$B$6,2026)+1)&"-"&RIGHT((IF(ISNUMBER(Assumptions!$B$6),Assumptions!$B$6,2026)+1+1),2) -> YEAR 2 • FY2027-28 | AA3: ="YEAR 3 • FY"&(IF(ISNUMBER(Assumptions!$B$6),Assumptions!$B$6,2026)+2)&"-"&RIGHT((IF(ISNUMBER(Assumptions!$B$6),Assumptions!$B$6,2026)+2+1),2) -> YEAR 3 • FY2028-29 | AM3: ="YEAR 4 • FY"&(IF(ISNUMBER(Assumptions!$B$6),Assumptions!$B$6,2026)+3)&"-"&RIGHT((IF(ISNUMBER(Assumptions!$B$6),Assumptions!$B$6,2026)+3+1),2) -> YEAR 4 • FY2029-30 | AY3: ="YEAR 5 • FY"&(IF(ISNUMBER(Assumptions!$B$6),Assumptions!$B$6,2026)+4)&"-"&RIGHT((IF(ISNUMBER(Assumptions!$B$6),Assumptions!$B$6,2026)+4+1),2) -> YEAR 5 • FY2030-31
A4: Month | B4: Unit | C4: =DATE(IF(ISNUMBER(Assumptions!$B$6),Assumptions!$B$6,2026),4+0,1) -> 46113 | D4: =DATE(IF(ISNUMBER(Assumptions!$B$6),Assumptions!$B$6,2026),4+1,1) -> 46143 | E4: =DATE(IF(ISNUMBER(Assumptions!$B$6),Assumptions!$B$6,2026),4+2,1) -> 46174 | F4: =DATE(IF(ISNUMBER(Assumptions!$B$6),Assumptions!$B$6,2026),4+3,1) -> 46204 | G4: =DATE(IF(ISNUMBER(Assumptions!$B$6),Assumptions!$B$6,2026),4+4,1) -> 46235 | H4: =DATE(IF(ISNUMBER(Assumptions!$B$6),Assumptions!$B$6,2026),4+5,1) -> 46266 | I4: =DATE(IF(ISNUMBER(Assumptions!$B$6),Assumptions!$B$6,2026),4+6,1) -> 46296 | J4: =DATE(IF(ISNUMBER(Assumptions!$B$6),Assumptions!$B$6,2026),4+7,1) -> 46327 | K4: =DATE(IF(ISNUMBER(Assumptions!$B$6),Assumptions!$B$6,2026),4+8,1) -> 46357 | L4: =DATE(IF(ISNUMBER(Assumptions!$B$6),Assumptions!$B$6,2026),4+9,1) -> 46388 | M4: =DATE(IF(ISNUMBER(Assumptions!$B$6),Assumptions!$B$6,2026),4+10,1) -> 46419 | N4: =DATE(IF(ISNUMBER(Assumptions!$B$6),Assumptions!$B$6,2026),4+11,1) -> 46447 | O4: =DATE(IF(ISNUMBER(Assumptions!$B$6),Assumptions!$B$6,2026),4+12,1) -> 46478 | P4: =DATE(IF(ISNUMBER(Assumptions!$B$6),Assumptions!$B$6,2026),4+13,1) -> 46508 | Q4: =DATE(IF(ISNUMBER(Assumptions!$B$6),Assumptions!$B$6,2026),4+14,1) -> 46539 | R4: =DATE(IF(ISNUMBER(Assumptions!$B$6),Assumptions!$B$6,2026),4+15,1) -> 46569 | S4: =DATE(IF(ISNUMBER(Assumptions!$B$6),Assumptions!$B$6,2026),4+16,1) -> 46600 | T4: =DATE(IF(ISNUMBER(Assumptions!$B$6),Assumptions!$B$6,2026),4+17,1) -> 46631 | U4: =DATE(IF(ISNUMBER(Assumptions!$B$6),Assumptions!$B$6,2026),4+18,1) -> 46661 | V4: =DATE(IF(ISNUMBER(Assumptions!$B$6),Assumptions!$B$6,2026),4+19,1) -> 46692 | W4: =DATE(IF(ISNUMBER(Assumptions!$B$6),Assumptions!$B$6,2026),4+20,1) -> 46722 | X4: =DATE(IF(ISNUMBER(Assumptions!$B$6),Assumptions!$B$6,2026),4+21,1) -> 46753 | Y4: =DATE(IF(ISNUMBER(Assumptions!$B$6),Assumptions!$B$6,2026),4+22,1) -> 46784 | Z4: =DATE(IF(ISNUMBER(Assumptions!$B$6),Assumptions!$B$6,2026),4+23,1) -> 46813 | AA4: =DATE(IF(ISNUMBER(Assumptions!$B$6),Assumptions!$B$6,2026),4+24,1) -> 46844 | AB4: =DATE(IF(ISNUMBER(Assumptions!$B$6),Assumptions!$B$6,2026),4+25,1) -> 46874 | AC4: =DATE(IF(ISNUMBER(Assumptions!$B$6),Assumptions!$B$6,2026),4+26,1) -> 46905 | AD4: =DATE(IF(ISNUMBER(Assumptions!$B$6),Assumptions!$B$6,2026),4+27,1) -> 46935 | AE4: =DATE(IF(ISNUMBER(Assumptions!$B$6),Assumptions!$B$6,2026),4+28,1) -> 46966 | AF4: =DATE(IF(ISNUMBER(Assumptions!$B$6),Assumptions!$B$6,2026),4+29,1) -> 46997 | AG4: =DATE(IF(ISNUMBER(Assumptions!$B$6),Assumptions!$B$6,2026),4+30,1) -> 47027 | AH4: =DATE(IF(ISNUMBER(Assumptions!$B$6),Assumptions!$B$6,2026),4+31,1) -> 47058 | AI4: =DATE(IF(ISNUMBER(Assumptions!$B$6),Assumptions!$B$6,2026),4+32,1) -> 47088 | AJ4: =DATE(IF(ISNUMBER(Assumptions!$B$6),Assumptions!$B$6,2026),4+33,1) -> 47119 | AK4: =DATE(IF(ISNUMBER(Assumptions!$B$6),Assumptions!$B$6,2026),4+34,1) -> 47150 | AL4: =DATE(IF(ISNUMBER(Assumptions!$B$6),Assumptions!$B$6,2026),4+35,1) -> 47178 | AM4: =DATE(IF(ISNUMBER(Assumptions!$B$6),Assumptions!$B$6,2026),4+36,1) -> 47209 | AN4: =DATE(IF(ISNUMBER(Assumptions!$B$6),Assumptions!$B$6,2026),4+37,1) -> 47239 | AO4: =DATE(IF(ISNUMBER(Assumptions!$B$6),Assumptions!$B$6,2026),4+38,1) -> 47270 | AP4: =DATE(IF(ISNUMBER(Assumptions!$B$6),Assumptions!$B$6,2026),4+39,1) -> 47300 | AQ4: =DATE(IF(ISNUMBER(Assumptions!$B$6),Assumptions!$B$6,2026),4+40,1) -> 47331 | AR4: =DATE(IF(ISNUMBER(Assumptions!$B$6),Assumptions!$B$6,2026),4+41,1) -> 47362 | AS4: =DATE(IF(ISNUMBER(Assumptions!$B$6),Assumptions!$B$6,2026),4+42,1) -> 47392 | AT4: =DATE(IF(ISNUMBER(Assumptions!$B$6),Assumptions!$B$6,2026),4+43,1) -> 47423 | AU4: =DATE(IF(ISNUMBER(Assumptions!$B$6),Assumptions!$B$6,2026),4+44,1) -> 47453 | AV4: =DATE(IF(ISNUMBER(Assumptions!$B$6),Assumptions!$B$6,2026),4+45,1) -> 47484 | AW4: =DATE(IF(ISNUMBER(Assumptions!$B$6),Assumptions!$B$6,2026),4+46,1) -> 47515 | AX4: =DATE(IF(ISNUMBER(Assumptions!$B$6),Assumptions!$B$6,2026),4+47,1) -> 47543 | AY4: =DATE(IF(ISNUMBER(Assumptions!$B$6),Assumptions!$B$6,2026),4+48,1) -> 47574 | AZ4: =DATE(IF(ISNUMBER(Assumptions!$B$6),Assumptions!$B$6,2026),4+49,1) -> 47604 | BA4: =DATE(IF(ISNUMBER(Assumptions!$B$6),Assumptions!$B$6,2026),4+50,1) -> 47635 | BB4: =DATE(IF(ISNUMBER(Assumptions!$B$6),Assumptions!$B$6,2026),4+51,1) -> 47665 | BC4: =DATE(IF(ISNUMBER(Assumptions!$B$6),Assumptions!$B$6,2026),4+52,1) -> 47696 | BD4: =DATE(IF(ISNUMBER(Assumptions!$B$6),Assumptions!$B$6,2026),4+53,1) -> 47727 | BE4: =DATE(IF(ISNUMBER(Assumptions!$B$6),Assumptions!$B$6,2026),4+54,1) -> 47757 | BF4: =DATE(IF(ISNUMBER(Assumptions!$B$6),Assumptions!$B$6,2026),4+55,1) -> 47788 | BG4: =DATE(IF(ISNUMBER(Assumptions!$B$6),Assumptions!$B$6,2026),4+56,1) -> 47818 | BH4: =DATE(IF(ISNUMBER(Assumptions!$B$6),Assumptions!$B$6,2026),4+57,1) -> 47849 | BI4: =DATE(IF(ISNUMBER(Assumptions!$B$6),Assumptions!$B$6,2026),4+58,1) -> 47880 | BJ4: =DATE(IF(ISNUMBER(Assumptions!$B$6),Assumptions!$B$6,2026),4+59,1) -> 47908
A5: Month # | C5: 1 | D5: 2 | E5: 3 | F5: 4 | G5: 5 | H5: 6 | I5: 7 | J5: 8 | K5: 9 | L5: 10 | M5: 11 | N5: 12 | O5: 13 | P5: 14 | Q5: 15 | R5: 16 | S5: 17 | T5: 18 | U5: 19 | V5: 20 | W5: 21 | X5: 22 | Y5: 23 | Z5: 24 | AA5: 25 | AB5: 26 | AC5: 27 | AD5: 28 | AE5: 29 | AF5: 30 | AG5: 31 | AH5: 32 | AI5: 33 | AJ5: 34 | AK5: 35 | AL5: 36 | AM5: 37 | AN5: 38 | AO5: 39 | AP5: 40 | AQ5: 41 | AR5: 42 | AS5: 43 | AT5: 44 | AU5: 45 | AV5: 46 | AW5: 47 | AX5: 48 | AY5: 49 | AZ5: 50 | BA5: 51 | BB5: 52 | BC5: 53 | BD5: 54 | BE5: 55 | BF5: 56 | BG5: 57 | BH5: 58 | BI5: 59 | BJ5: 60
A6: Year # | C6: 1 | D6: 1 | E6: 1 | F6: 1 | G6: 1 | H6: 1 | I6: 1 | J6: 1 | K6: 1 | L6: 1 | M6: 1 | N6: 1 | O6: 2 | P6: 2 | Q6: 2 | R6: 2 | S6: 2 | T6: 2 | U6: 2 | V6: 2 | W6: 2 | X6: 2 | Y6: 2 | Z6: 2 | AA6: 3 | AB6: 3 | AC6: 3 | AD6: 3 | AE6: 3 | AF6: 3 | AG6: 3 | AH6: 3 | AI6: 3 | AJ6: 3 | AK6: 3 | AL6: 3 | AM6: 4 | AN6: 4 | AO6: 4 | AP6: 4 | AQ6: 4 | AR6: 4 | AS6: 4 | AT6: 4 | AU6: 4 | AV6: 4 | AW6: 4 | AX6: 4 | AY6: 5 | AZ6: 5 | BA6: 5 | BB6: 5 | BC6: 5 | BD6: 5 | BE6: 5 | BF6: 5 | BG6: 5 | BH6: 5 | BI6: 5 | BJ6: 5
A7: Capacity utilisation | B7: % | C7: =IFERROR(Assumptions!$B$16,"") -> 0 | D7: =IFERROR(Assumptions!$B$17,"") -> 0 | E7: =IFERROR(Assumptions!$B$18,"") -> 0 | F7: =IFERROR(Assumptions!$B$19,"") -> 0 | G7: =IFERROR(Assumptions!$B$20,"") -> 0 | H7: =IFERROR(Assumptions!$B$21,"") -> 0 | I7: =IFERROR(Assumptions!$B$22,"") -> 0 | J7: =IFERROR(Assumptions!$B$23,"") -> 0 | K7: =IFERROR(Assumptions!$B$24,"") -> 0 | L7: =IFERROR(Assumptions!$B$25,"") -> 0 | M7: =IFERROR(Assumptions!$B$26,"") -> 0 | N7: =IFERROR(Assumptions!$B$27,"") -> 0 | O7: =IFERROR(Assumptions!$B$28,"") -> 0 | P7: =IFERROR(Assumptions!$B$28,"") -> 0 | Q7: =IFERROR(Assumptions!$B$28,"") -> 0 | R7: =IFERROR(Assumptions!$B$28,"") -> 0 | S7: =IFERROR(Assumptions!$B$28,"") -> 0 | T7: =IFERROR(Assumptions!$B$28,"") -> 0 | U7: =IFERROR(Assumptions!$B$28,"") -> 0 | V7: =IFERROR(Assumptions!$B$28,"") -> 0 | ... Z7: =IFERROR(Assumptions!$B$28,"") -> 0 | AA7: =IFERROR(Assumptions!$B$29,"") -> 0 | AB7: =IFERROR(Assumptions!$B$29,"") -> 0 | AC7: =IFERROR(Assumptions!$B$29,"") -> 0 | AD7: =IFERROR(Assumptions!$B$29,"") -> 0 | AE7: =IFERROR(Assumptions!$B$29,"") -> 0 | AF7: =IFERROR(Assumptions!$B$29,"") -> 0 | AG7: =IFERROR(Assumptions!$B$29,"") -> 0 | AH7: =IFERROR(Assumptions!$B$29,"") -> 0 | ... AL7: =IFERROR(Assumptions!$B$29,"") -> 0 | AM7: =IFERROR(Assumptions!$B$30,"") -> 0 | AN7: =IFERROR(Assumptions!$B$30,"") -> 0 | AO7: =IFERROR(Assumptions!$B$30,"") -> 0 | AP7: =IFERROR(Assumptions!$B$30,"") -> 0 | AQ7: =IFERROR(Assumptions!$B$30,"") -> 0 | AR7: =IFERROR(Assumptions!$B$30,"") -> 0 | AS7: =IFERROR(Assumptions!$B$30,"") -> 0 | AT7: =IFERROR(Assumptions!$B$30,"") -> 0 | ... AX7: =IFERROR(Assumptions!$B$30,"") -> 0 | AY7: =IFERROR(Assumptions!$B$31,"") -> 0 | AZ7: =IFERROR(Assumptions!$B$31,"") -> 0 | BA7: =IFERROR(Assumptions!$B$31,"") -> 0 | BB7: =IFERROR(Assumptions!$B$31,"") -> 0 | BC7: =IFERROR(Assumptions!$B$31,"") -> 0 | BD7: =IFERROR(Assumptions!$B$31,"") -> 0 | BE7: =IFERROR(Assumptions!$B$31,"") -> 0 | BF7: =IFERROR(Assumptions!$B$31,"") -> 0 | ... BJ7: =IFERROR(Assumptions!$B$31,"") -> 0
A8: =IFERROR(INDEX('Industry Labels'!$C$5:$Z$5,MATCH(Assumptions!$B$3,'Industry Labels'!$C$4:$Z$4,0)),"Installed / service capacity") -> Installed / service capacity | B8: =IFERROR(INDEX('Industry Labels'!$C$6:$Z$6,MATCH(Assumptions!$B$3,'Industry Labels'!$C$4:$Z$4,0)),"units/month") -> units/month | C8: =IFERROR(Assumptions!$B$5,"") -> 0 | D8: =IFERROR(Assumptions!$B$5,"") -> 0 | E8: =IFERROR(Assumptions!$B$5,"") -> 0 | F8: =IFERROR(Assumptions!$B$5,"") -> 0 | G8: =IFERROR(Assumptions!$B$5,"") -> 0 | H8: =IFERROR(Assumptions!$B$5,"") -> 0 | I8: =IFERROR(Assumptions!$B$5,"") -> 0 | J8: =IFERROR(Assumptions!$B$5,"") -> 0 | ... BJ8: =IFERROR(Assumptions!$B$5,"") -> 0
A9: Output delivered (volume) | B9: =IFERROR(INDEX('Industry Labels'!$C$7:$Z$7,MATCH(Assumptions!$B$3,'Industry Labels'!$C$4:$Z$4,0)),"units") -> units | C9: =IFERROR(C8*C7,"") -> 0 | D9: =IFERROR(D8*D7,"") -> 0 | E9: =IFERROR(E8*E7,"") -> 0 | F9: =IFERROR(F8*F7,"") -> 0 | G9: =IFERROR(G8*G7,"") -> 0 | H9: =IFERROR(H8*H7,"") -> 0 | I9: =IFERROR(I8*I7,"") -> 0 | J9: =IFERROR(J8*J7,"") -> 0 | ... BJ9: =IFERROR(BJ8*BJ7,"") -> 0
A10: Sales volume | B10: =IFERROR(INDEX('Industry Labels'!$C$7:$Z$7,MATCH(Assumptions!$B$3,'Industry Labels'!$C$4:$Z$4,0)),"units") -> units | C10: =IFERROR(C9,"") -> 0 | D10: =IFERROR(D9,"") -> 0 | E10: =IFERROR(E9,"") -> 0 | F10: =IFERROR(F9,"") -> 0 | G10: =IFERROR(G9,"") -> 0 | H10: =IFERROR(H9,"") -> 0 | I10: =IFERROR(I9,"") -> 0 | J10: =IFERROR(J9,"") -> 0 | ... BJ10: =IFERROR(BJ9,"") -> 0
A11: Realisation | B11: ="₹/"&IFERROR(INDEX('Industry Labels'!$C$8:$Z$8,MATCH(Assumptions!$B$3,'Industry Labels'!$C$4:$Z$4,0)),"unit") -> ₹/unit | C11: =IFERROR(Assumptions!$B$10*(1+Assumptions!$B$33)^(C6-1),"") -> 0 | D11: =IFERROR(Assumptions!$B$10*(1+Assumptions!$B$33)^(D6-1),"") -> 0 | E11: =IFERROR(Assumptions!$B$10*(1+Assumptions!$B$33)^(E6-1),"") -> 0 | F11: =IFERROR(Assumptions!$B$10*(1+Assumptions!$B$33)^(F6-1),"") -> 0 | G11: =IFERROR(Assumptions!$B$10*(1+Assumptions!$B$33)^(G6-1),"") -> 0 | H11: =IFERROR(Assumptions!$B$10*(1+Assumptions!$B$33)^(H6-1),"") -> 0 | I11: =IFERROR(Assumptions!$B$10*(1+Assumptions!$B$33)^(I6-1),"") -> 0 | J11: =IFERROR(Assumptions!$B$10*(1+Assumptions!$B$33)^(J6-1),"") -> 0 | ... BJ11: =IFERROR(Assumptions!$B$10*(1+Assumptions!$B$33)^(BJ6-1),"") -> 0
A12: NET SALES | B12: ₹ L | C12: =IFERROR(C10*C11/100000,"") -> 0 | D12: =IFERROR(D10*D11/100000,"") -> 0 | E12: =IFERROR(E10*E11/100000,"") -> 0 | F12: =IFERROR(F10*F11/100000,"") -> 0 | G12: =IFERROR(G10*G11/100000,"") -> 0 | H12: =IFERROR(H10*H11/100000,"") -> 0 | I12: =IFERROR(I10*I11/100000,"") -> 0 | J12: =IFERROR(J10*J11/100000,"") -> 0 | ... BJ12: =IFERROR(BJ10*BJ11/100000,"") -> 0

Sheet Profitability (Monthly)
A1: PROFITABILITY STATEMENT (monthly, 5 years) — ₹ Lakh
A2: Every line links to Assumptions / Production & Sales / Term Loan / Working Capital. Escalation applied by year.
C3: ="YEAR 1 • FY"&(IF(ISNUMBER(Assumptions!$B$6),Assumptions!$B$6,2026)+0)&"-"&RIGHT((IF(ISNUMBER(Assumptions!$B$6),Assumptions!$B$6,2026)+0+1),2) -> YEAR 1 • FY2026-27 | O3: ="YEAR 2 • FY"&(IF(ISNUMBER(Assumptions!$B$6),Assumptions!$B$6,2026)+1)&"-"&RIGHT((IF(ISNUMBER(Assumptions!$B$6),Assumptions!$B$6,2026)+1+1),2) -> YEAR 2 • FY2027-28 | AA3: ="YEAR 3 • FY"&(IF(ISNUMBER(Assumptions!$B$6),Assumptions!$B$6,2026)+2)&"-"&RIGHT((IF(ISNUMBER(Assumptions!$B$6),Assumptions!$B$6,2026)+2+1),2) -> YEAR 3 • FY2028-29 | AM3: ="YEAR 4 • FY"&(IF(ISNUMBER(Assumptions!$B$6),Assumptions!$B$6,2026)+3)&"-"&RIGHT((IF(ISNUMBER(Assumptions!$B$6),Assumptions!$B$6,2026)+3+1),2) -> YEAR 4 • FY2029-30 | AY3: ="YEAR 5 • FY"&(IF(ISNUMBER(Assumptions!$B$6),Assumptions!$B$6,2026)+4)&"-"&RIGHT((IF(ISNUMBER(Assumptions!$B$6),Assumptions!$B$6,2026)+4+1),2) -> YEAR 5 • FY2030-31
A4: Month | B4: Unit | C4: =DATE(IF(ISNUMBER(Assumptions!$B$6),Assumptions!$B$6,2026),4+0,1) -> 46113 | D4: =DATE(IF(ISNUMBER(Assumptions!$B$6),Assumptions!$B$6,2026),4+1,1) -> 46143 | E4: =DATE(IF(ISNUMBER(Assumptions!$B$6),Assumptions!$B$6,2026),4+2,1) -> 46174 | F4: =DATE(IF(ISNUMBER(Assumptions!$B$6),Assumptions!$B$6,2026),4+3,1) -> 46204 | G4: =DATE(IF(ISNUMBER(Assumptions!$B$6),Assumptions!$B$6,2026),4+4,1) -> 46235 | H4: =DATE(IF(ISNUMBER(Assumptions!$B$6),Assumptions!$B$6,2026),4+5,1) -> 46266 | I4: =DATE(IF(ISNUMBER(Assumptions!$B$6),Assumptions!$B$6,2026),4+6,1) -> 46296 | J4: =DATE(IF(ISNUMBER(Assumptions!$B$6),Assumptions!$B$6,2026),4+7,1) -> 46327 | K4: =DATE(IF(ISNUMBER(Assumptions!$B$6),Assumptions!$B$6,2026),4+8,1) -> 46357 | L4: =DATE(IF(ISNUMBER(Assumptions!$B$6),Assumptions!$B$6,2026),4+9,1) -> 46388 | M4: =DATE(IF(ISNUMBER(Assumptions!$B$6),Assumptions!$B$6,2026),4+10,1) -> 46419 | N4: =DATE(IF(ISNUMBER(Assumptions!$B$6),Assumptions!$B$6,2026),4+11,1) -> 46447 | O4: =DATE(IF(ISNUMBER(Assumptions!$B$6),Assumptions!$B$6,2026),4+12,1) -> 46478 | P4: =DATE(IF(ISNUMBER(Assumptions!$B$6),Assumptions!$B$6,2026),4+13,1) -> 46508 | Q4: =DATE(IF(ISNUMBER(Assumptions!$B$6),Assumptions!$B$6,2026),4+14,1) -> 46539 | R4: =DATE(IF(ISNUMBER(Assumptions!$B$6),Assumptions!$B$6,2026),4+15,1) -> 46569 | S4: =DATE(IF(ISNUMBER(Assumptions!$B$6),Assumptions!$B$6,2026),4+16,1) -> 46600 | T4: =DATE(IF(ISNUMBER(Assumptions!$B$6),Assumptions!$B$6,2026),4+17,1) -> 46631 | U4: =DATE(IF(ISNUMBER(Assumptions!$B$6),Assumptions!$B$6,2026),4+18,1) -> 46661 | V4: =DATE(IF(ISNUMBER(Assumptions!$B$6),Assumptions!$B$6,2026),4+19,1) -> 46692 | W4: =DATE(IF(ISNUMBER(Assumptions!$B$6),Assumptions!$B$6,2026),4+20,1) -> 46722 | X4: =DATE(IF(ISNUMBER(Assumptions!$B$6),Assumptions!$B$6,2026),4+21,1) -> 46753 | Y4: =DATE(IF(ISNUMBER(Assumptions!$B$6),Assumptions!$B$6,2026),4+22,1) -> 46784 | Z4: =DATE(IF(ISNUMBER(Assumptions!$B$6),Assumptions!$B$6,2026),4+23,1) -> 46813 | AA4: =DATE(IF(ISNUMBER(Assumptions!$B$6),Assumptions!$B$6,2026),4+24,1) -> 46844 | AB4: =DATE(IF(ISNUMBER(Assumptions!$B$6),Assumptions!$B$6,2026),4+25,1) -> 46874 | AC4: =DATE(IF(ISNUMBER(Assumptions!$B$6),Assumptions!$B$6,2026),4+26,1) -> 46905 | AD4: =DATE(IF(ISNUMBER(Assumptions!$B$6),Assumptions!$B$6,2026),4+27,1) -> 46935 | AE4: =DATE(IF(ISNUMBER(Assumptions!$B$6),Assumptions!$B$6,2026),4+28,1) -> 46966 | AF4: =DATE(IF(ISNUMBER(Assumptions!$B$6),Assumptions!$B$6,2026),4+29,1) -> 46997 | AG4: =DATE(IF(ISNUMBER(Assumptions!$B$6),Assumptions!$B$6,2026),4+30,1) -> 47027 | AH4: =DATE(IF(ISNUMBER(Assumptions!$B$6),Assumptions!$B$6,2026),4+31,1) -> 47058 | AI4: =DATE(IF(ISNUMBER(Assumptions!$B$6),Assumptions!$B$6,2026),4+32,1) -> 47088 | AJ4: =DATE(IF(ISNUMBER(Assumptions!$B$6),Assumptions!$B$6,2026),4+33,1) -> 47119 | AK4: =DATE(IF(ISNUMBER(Assumptions!$B$6),Assumptions!$B$6,2026),4+34,1) -> 47150 | AL4: =DATE(IF(ISNUMBER(Assumptions!$B$6),Assumptions!$B$6,2026),4+35,1) -> 47178 | AM4: =DATE(IF(ISNUMBER(Assumptions!$B$6),Assumptions!$B$6,2026),4+36,1) -> 47209 | AN4: =DATE(IF(ISNUMBER(Assumptions!$B$6),Assumptions!$B$6,2026),4+37,1) -> 47239 | AO4: =DATE(IF(ISNUMBER(Assumptions!$B$6),Assumptions!$B$6,2026),4+38,1) -> 47270 | AP4: =DATE(IF(ISNUMBER(Assumptions!$B$6),Assumptions!$B$6,2026),4+39,1) -> 47300 | AQ4: =DATE(IF(ISNUMBER(Assumptions!$B$6),Assumptions!$B$6,2026),4+40,1) -> 47331 | AR4: =DATE(IF(ISNUMBER(Assumptions!$B$6),Assumptions!$B$6,2026),4+41,1) -> 47362 | AS4: =DATE(IF(ISNUMBER(Assumptions!$B$6),Assumptions!$B$6,2026),4+42,1) -> 47392 | AT4: =DATE(IF(ISNUMBER(Assumptions!$B$6),Assumptions!$B$6,2026),4+43,1) -> 47423 | AU4: =DATE(IF(ISNUMBER(Assumptions!$B$6),Assumptions!$B$6,2026),4+44,1) -> 47453 | AV4: =DATE(IF(ISNUMBER(Assumptions!$B$6),Assumptions!$B$6,2026),4+45,1) -> 47484 | AW4: =DATE(IF(ISNUMBER(Assumptions!$B$6),Assumptions!$B$6,2026),4+46,1) -> 47515 | AX4: =DATE(IF(ISNUMBER(Assumptions!$B$6),Assumptions!$B$6,2026),4+47,1) -> 47543 | AY4: =DATE(IF(ISNUMBER(Assumptions!$B$6),Assumptions!$B$6,2026),4+48,1) -> 47574 | AZ4: =DATE(IF(ISNUMBER(Assumptions!$B$6),Assumptions!$B$6,2026),4+49,1) -> 47604 | BA4: =DATE(IF(ISNUMBER(Assumptions!$B$6),Assumptions!$B$6,2026),4+50,1) -> 47635 | BB4: =DATE(IF(ISNUMBER(Assumptions!$B$6),Assumptions!$B$6,2026),4+51,1) -> 47665 | BC4: =DATE(IF(ISNUMBER(Assumptions!$B$6),Assumptions!$B$6,2026),4+52,1) -> 47696 | BD4: =DATE(IF(ISNUMBER(Assumptions!$B$6),Assumptions!$B$6,2026),4+53,1) -> 47727 | BE4: =DATE(IF(ISNUMBER(Assumptions!$B$6),Assumptions!$B$6,2026),4+54,1) -> 47757 | BF4: =DATE(IF(ISNUMBER(Assumptions!$B$6),Assumptions!$B$6,2026),4+55,1) -> 47788 | BG4: =DATE(IF(ISNUMBER(Assumptions!$B$6),Assumptions!$B$6,2026),4+56,1) -> 47818 | BH4: =DATE(IF(ISNUMBER(Assumptions!$B$6),Assumptions!$B$6,2026),4+57,1) -> 47849 | BI4: =DATE(IF(ISNUMBER(Assumptions!$B$6),Assumptions!$B$6,2026),4+58,1) -> 47880 | BJ4: =DATE(IF(ISNUMBER(Assumptions!$B$6),Assumptions!$B$6,2026),4+59,1) -> 47908
A5: Month # | C5: 1 | D5: 2 | E5: 3 | F5: 4 | G5: 5 | H5: 6 | I5: 7 | J5: 8 | K5: 9 | L5: 10 | M5: 11 | N5: 12 | O5: 13 | P5: 14 | Q5: 15 | R5: 16 | S5: 17 | T5: 18 | U5: 19 | V5: 20 | W5: 21 | X5: 22 | Y5: 23 | Z5: 24 | AA5: 25 | AB5: 26 | AC5: 27 | AD5: 28 | AE5: 29 | AF5: 30 | AG5: 31 | AH5: 32 | AI5: 33 | AJ5: 34 | AK5: 35 | AL5: 36 | AM5: 37 | AN5: 38 | AO5: 39 | AP5: 40 | AQ5: 41 | AR5: 42 | AS5: 43 | AT5: 44 | AU5: 45 | AV5: 46 | AW5: 47 | AX5: 48 | AY5: 49 | AZ5: 50 | BA5: 51 | BB5: 52 | BC5: 53 | BD5: 54 | BE5: 55 | BF5: 56 | BG5: 57 | BH5: 58 | BI5: 59 | BJ5: 60
A6: Year # | C6: 1 | D6: 1 | E6: 1 | F6: 1 | G6: 1 | H6: 1 | I6: 1 | J6: 1 | K6: 1 | L6: 1 | M6: 1 | N6: 1 | O6: 2 | P6: 2 | Q6: 2 | R6: 2 | S6: 2 | T6: 2 | U6: 2 | V6: 2 | W6: 2 | X6: 2 | Y6: 2 | Z6: 2 | AA6: 3 | AB6: 3 | AC6: 3 | AD6: 3 | AE6: 3 | AF6: 3 | AG6: 3 | AH6: 3 | AI6: 3 | AJ6: 3 | AK6: 3 | AL6: 3 | AM6: 4 | AN6: 4 | AO6: 4 | AP6: 4 | AQ6: 4 | AR6: 4 | AS6: 4 | AT6: 4 | AU6: 4 | AV6: 4 | AW6: 4 | AX6: 4 | AY6: 5 | AZ6: 5 | BA6: 5 | BB6: 5 | BC6: 5 | BD6: 5 | BE6: 5 | BF6: 5 | BG6: 5 | BH6: 5 | BI6: 5 | BJ6: 5
A7: A. REVENUE
A8: Net Sales (net of GST) | B8: ₹ L | C8: =IFERROR('Production & Sales'!C12,"") -> 0 | D8: =IFERROR('Production & Sales'!D12,"") -> 0 | E8: =IFERROR('Production & Sales'!E12,"") -> 0 | F8: =IFERROR('Production & Sales'!F12,"") -> 0 | G8: =IFERROR('Production & Sales'!G12,"") -> 0 | H8: =IFERROR('Production & Sales'!H12,"") -> 0 | I8: =IFERROR('Production & Sales'!I12,"") -> 0 | J8: =IFERROR('Production & Sales'!J12,"") -> 0 | ... BJ8: =IFERROR('Production & Sales'!BJ12,"") -> 0
A9: =IFERROR(INDEX('Industry Labels'!$C$20:$Z$20,MATCH(Assumptions!$B$3,'Industry Labels'!$C$4:$Z$4,0)),"B. VARIABLE / DIRECT COST") -> B. VARIABLE / DIRECT COST
A10: =IFERROR(INDEX('Industry Labels'!$C$21:$Z$21,MATCH(Assumptions!$B$3,'Industry Labels'!$C$4:$Z$4,0)),"Direct cost consumed") -> Direct cost consumed | B10: ₹ L | C10: =IFERROR('Production & Sales'!C9*Assumptions!$B$11*(1+Assumptions!$B$34)^(C6-1)/100000,"") -> 0 | D10: =IFERROR('Production & Sales'!D9*Assumptions!$B$11*(1+Assumptions!$B$34)^(D6-1)/100000,"") -> 0 | E10: =IFERROR('Production & Sales'!E9*Assumptions!$B$11*(1+Assumptions!$B$34)^(E6-1)/100000,"") -> 0 | F10: =IFERROR('Production & Sales'!F9*Assumptions!$B$11*(1+Assumptions!$B$34)^(F6-1)/100000,"") -> 0 | G10: =IFERROR('Production & Sales'!G9*Assumptions!$B$11*(1+Assumptions!$B$34)^(G6-1)/100000,"") -> 0 | H10: =IFERROR('Production & Sales'!H9*Assumptions!$B$11*(1+Assumptions!$B$34)^(H6-1)/100000,"") -> 0 | I10: =IFERROR('Production & Sales'!I9*Assumptions!$B$11*(1+Assumptions!$B$34)^(I6-1)/100000,"") -> 0 | J10: =IFERROR('Production & Sales'!J9*Assumptions!$B$11*(1+Assumptions!$B$34)^(J6-1)/100000,"") -> 0 | ... BJ10: =IFERROR('Production & Sales'!BJ9*Assumptions!$B$11*(1+Assumptions!$B$34)^(BJ6-1)/100000,"") -> 0
A11: =IFERROR(INDEX('Industry Labels'!$C$22:$Z$22,MATCH(Assumptions!$B$3,'Industry Labels'!$C$4:$Z$4,0)),"Utilities & energy")&" (variable)" -> Utilities & energy (variable) | B11: ₹ L | C11: =IFERROR('Production & Sales'!C9*Assumptions!$B$39*(1+Assumptions!$B$35)^(C6-1)/100000,"") -> 0 | D11: =IFERROR('Production & Sales'!D9*Assumptions!$B$39*(1+Assumptions!$B$35)^(D6-1)/100000,"") -> 0 | E11: =IFERROR('Production & Sales'!E9*Assumptions!$B$39*(1+Assumptions!$B$35)^(E6-1)/100000,"") -> 0 | F11: =IFERROR('Production & Sales'!F9*Assumptions!$B$39*(1+Assumptions!$B$35)^(F6-1)/100000,"") -> 0 | G11: =IFERROR('Production & Sales'!G9*Assumptions!$B$39*(1+Assumptions!$B$35)^(G6-1)/100000,"") -> 0 | H11: =IFERROR('Production & Sales'!H9*Assumptions!$B$39*(1+Assumptions!$B$35)^(H6-1)/100000,"") -> 0 | I11: =IFERROR('Production & Sales'!I9*Assumptions!$B$39*(1+Assumptions!$B$35)^(I6-1)/100000,"") -> 0 | J11: =IFERROR('Production & Sales'!J9*Assumptions!$B$39*(1+Assumptions!$B$35)^(J6-1)/100000,"") -> 0 | ... BJ11: =IFERROR('Production & Sales'!BJ9*Assumptions!$B$39*(1+Assumptions!$B$35)^(BJ6-1)/100000,"") -> 0
A12: =IFERROR(INDEX('Industry Labels'!$C$23:$Z$23,MATCH(Assumptions!$B$3,'Industry Labels'!$C$4:$Z$4,0)),"Consumables, supplies & packing") -> Consumables, supplies & packing | B12: ₹ L | C12: =IFERROR('Production & Sales'!C9*(Assumptions!$B$40+Assumptions!$B$41)*(1+Assumptions!$B$37)^(C6-1)/100000,"") -> 0 | D12: =IFERROR('Production & Sales'!D9*(Assumptions!$B$40+Assumptions!$B$41)*(1+Assumptions!$B$37)^(D6-1)/100000,"") -> 0 | E12: =IFERROR('Production & Sales'!E9*(Assumptions!$B$40+Assumptions!$B$41)*(1+Assumptions!$B$37)^(E6-1)/100000,"") -> 0 | F12: =IFERROR('Production & Sales'!F9*(Assumptions!$B$40+Assumptions!$B$41)*(1+Assumptions!$B$37)^(F6-1)/100000,"") -> 0 | G12: =IFERROR('Production & Sales'!G9*(Assumptions!$B$40+Assumptions!$B$41)*(1+Assumptions!$B$37)^(G6-1)/100000,"") -> 0 | H12: =IFERROR('Production & Sales'!H9*(Assumptions!$B$40+Assumptions!$B$41)*(1+Assumptions!$B$37)^(H6-1)/100000,"") -> 0 | I12: =IFERROR('Production & Sales'!I9*(Assumptions!$B$40+Assumptions!$B$41)*(1+Assumptions!$B$37)^(I6-1)/100000,"") -> 0 | J12: =IFERROR('Production & Sales'!J9*(Assumptions!$B$40+Assumptions!$B$41)*(1+Assumptions!$B$37)^(J6-1)/100000,"") -> 0 | ... BJ12: =IFERROR('Production & Sales'!BJ9*(Assumptions!$B$40+Assumptions!$B$41)*(1+Assumptions!$B$37)^(BJ6-1)/100000,"") -> 0
A13: Direct labour | B13: ₹ L | C13: =IFERROR(Assumptions!$B$42*(1+Assumptions!$B$36)^(C6-1),"") -> 0 | D13: =IFERROR(Assumptions!$B$42*(1+Assumptions!$B$36)^(D6-1),"") -> 0 | E13: =IFERROR(Assumptions!$B$42*(1+Assumptions!$B$36)^(E6-1),"") -> 0 | F13: =IFERROR(Assumptions!$B$42*(1+Assumptions!$B$36)^(F6-1),"") -> 0 | G13: =IFERROR(Assumptions!$B$42*(1+Assumptions!$B$36)^(G6-1),"") -> 0 | H13: =IFERROR(Assumptions!$B$42*(1+Assumptions!$B$36)^(H6-1),"") -> 0 | I13: =IFERROR(Assumptions!$B$42*(1+Assumptions!$B$36)^(I6-1),"") -> 0 | J13: =IFERROR(Assumptions!$B$42*(1+Assumptions!$B$36)^(J6-1),"") -> 0 | ... BJ13: =IFERROR(Assumptions!$B$42*(1+Assumptions!$B$36)^(BJ6-1),"") -> 0
A14: Total variable / direct cost | B14: ₹ L | C14: =IFERROR(SUM(C10:C13),"") -> 0 | D14: =IFERROR(SUM(D10:D13),"") -> 0 | E14: =IFERROR(SUM(E10:E13),"") -> 0 | F14: =IFERROR(SUM(F10:F13),"") -> 0 | G14: =IFERROR(SUM(G10:G13),"") -> 0 | H14: =IFERROR(SUM(H10:H13),"") -> 0 | I14: =IFERROR(SUM(I10:I13),"") -> 0 | J14: =IFERROR(SUM(J10:J13),"") -> 0 | ... BJ14: =IFERROR(SUM(BJ10:BJ13),"") -> 0
A15: CONTRIBUTION (Gross margin) | B15: ₹ L | C15: =IFERROR(C8-C14,"") -> 0 | D15: =IFERROR(D8-D14,"") -> 0 | E15: =IFERROR(E8-E14,"") -> 0 | F15: =IFERROR(F8-F14,"") -> 0 | G15: =IFERROR(G8-G14,"") -> 0 | H15: =IFERROR(H8-H14,"") -> 0 | I15: =IFERROR(I8-I14,"") -> 0 | J15: =IFERROR(J8-J14,"") -> 0 | ... BJ15: =IFERROR(BJ8-BJ14,"") -> 0
A16: Contribution margin | B16: % | C16: =IFERROR(IF(C8=0,0,C15/C8),"") -> 0 | D16: =IFERROR(IF(D8=0,0,D15/D8),"") -> 0 | E16: =IFERROR(IF(E8=0,0,E15/E8),"") -> 0 | F16: =IFERROR(IF(F8=0,0,F15/F8),"") -> 0 | G16: =IFERROR(IF(G8=0,0,G15/G8),"") -> 0 | H16: =IFERROR(IF(H8=0,0,H15/H8),"") -> 0 | I16: =IFERROR(IF(I8=0,0,I15/I8),"") -> 0 | J16: =IFERROR(IF(J8=0,0,J15/J8),"") -> 0 | ... BJ16: =IFERROR(IF(BJ8=0,0,BJ15/BJ8),"") -> 0
A17: C. FIXED & OVERHEAD COST
A18: Admin & management salaries | B18: ₹ L | C18: =IFERROR(Assumptions!$B$44*(1+Assumptions!$B$36)^(C6-1),"") -> 0 | D18: =IFERROR(Assumptions!$B$44*(1+Assumptions!$B$36)^(D6-1),"") -> 0 | E18: =IFERROR(Assumptions!$B$44*(1+Assumptions!$B$36)^(E6-1),"") -> 0 | F18: =IFERROR(Assumptions!$B$44*(1+Assumptions!$B$36)^(F6-1),"") -> 0 | G18: =IFERROR(Assumptions!$B$44*(1+Assumptions!$B$36)^(G6-1),"") -> 0 | H18: =IFERROR(Assumptions!$B$44*(1+Assumptions!$B$36)^(H6-1),"") -> 0 | I18: =IFERROR(Assumptions!$B$44*(1+Assumptions!$B$36)^(I6-1),"") -> 0 | J18: =IFERROR(Assumptions!$B$44*(1+Assumptions!$B$36)^(J6-1),"") -> 0 | ... BJ18: =IFERROR(Assumptions!$B$44*(1+Assumptions!$B$36)^(BJ6-1),"") -> 0
A19: =IFERROR(INDEX('Industry Labels'!$C$24:$Z$24,MATCH(Assumptions!$B$3,'Industry Labels'!$C$4:$Z$4,0)),"Fixed utility / facility charges") -> Fixed utility / facility charges | B19: ₹ L | C19: =IFERROR(Assumptions!$B$45*(1+Assumptions!$B$35)^(C6-1),"") -> 0 | D19: =IFERROR(Assumptions!$B$45*(1+Assumptions!$B$35)^(D6-1),"") -> 0 | E19: =IFERROR(Assumptions!$B$45*(1+Assumptions!$B$35)^(E6-1),"") -> 0 | F19: =IFERROR(Assumptions!$B$45*(1+Assumptions!$B$35)^(F6-1),"") -> 0 | G19: =IFERROR(Assumptions!$B$45*(1+Assumptions!$B$35)^(G6-1),"") -> 0 | H19: =IFERROR(Assumptions!$B$45*(1+Assumptions!$B$35)^(H6-1),"") -> 0 | I19: =IFERROR(Assumptions!$B$45*(1+Assumptions!$B$35)^(I6-1),"") -> 0 | J19: =IFERROR(Assumptions!$B$45*(1+Assumptions!$B$35)^(J6-1),"") -> 0 | ... BJ19: =IFERROR(Assumptions!$B$45*(1+Assumptions!$B$35)^(BJ6-1),"") -> 0
A20: Repairs & maintenance | B20: ₹ L | C20: =IFERROR(('Project Cost'!$C$7+'Project Cost'!$C$11)*Assumptions!$B$46/12*(1+Assumptions!$B$37)^(C6-1),"") -> 0 | D20: =IFERROR(('Project Cost'!$C$7+'Project Cost'!$C$11)*Assumptions!$B$46/12*(1+Assumptions!$B$37)^(D6-1),"") -> 0 | E20: =IFERROR(('Project Cost'!$C$7+'Project Cost'!$C$11)*Assumptions!$B$46/12*(1+Assumptions!$B$37)^(E6-1),"") -> 0 | F20: =IFERROR(('Project Cost'!$C$7+'Project Cost'!$C$11)*Assumptions!$B$46/12*(1+Assumptions!$B$37)^(F6-1),"") -> 0 | G20: =IFERROR(('Project Cost'!$C$7+'Project Cost'!$C$11)*Assumptions!$B$46/12*(1+Assumptions!$B$37)^(G6-1),"") -> 0 | H20: =IFERROR(('Project Cost'!$C$7+'Project Cost'!$C$11)*Assumptions!$B$46/12*(1+Assumptions!$B$37)^(H6-1),"") -> 0 | I20: =IFERROR(('Project Cost'!$C$7+'Project Cost'!$C$11)*Assumptions!$B$46/12*(1+Assumptions!$B$37)^(I6-1),"") -> 0 | J20: =IFERROR(('Project Cost'!$C$7+'Project Cost'!$C$11)*Assumptions!$B$46/12*(1+Assumptions!$B$37)^(J6-1),"") -> 0 | ... BJ20: =IFERROR(('Project Cost'!$C$7+'Project Cost'!$C$11)*Assumptions!$B$46/12*(1+Assumptions!$B$37)^(BJ6-1),"") -> 0
A21: Insurance | B21: ₹ L | C21: =IFERROR(('Project Cost'!$C$14-'Project Cost'!$C$5-'Project Cost'!$C$13)*Assumptions!$B$47/12*(1+Assumptions!$B$37)^(C6-1),"") -> 0 | D21: =IFERROR(('Project Cost'!$C$14-'Project Cost'!$C$5-'Project Cost'!$C$13)*Assumptions!$B$47/12*(1+Assumptions!$B$37)^(D6-1),"") -> 0 | E21: =IFERROR(('Project Cost'!$C$14-'Project Cost'!$C$5-'Project Cost'!$C$13)*Assumptions!$B$47/12*(1+Assumptions!$B$37)^(E6-1),"") -> 0 | F21: =IFERROR(('Project Cost'!$C$14-'Project Cost'!$C$5-'Project Cost'!$C$13)*Assumptions!$B$47/12*(1+Assumptions!$B$37)^(F6-1),"") -> 0 | G21: =IFERROR(('Project Cost'!$C$14-'Project Cost'!$C$5-'Project Cost'!$C$13)*Assumptions!$B$47/12*(1+Assumptions!$B$37)^(G6-1),"") -> 0 | H21: =IFERROR(('Project Cost'!$C$14-'Project Cost'!$C$5-'Project Cost'!$C$13)*Assumptions!$B$47/12*(1+Assumptions!$B$37)^(H6-1),"") -> 0 | I21: =IFERROR(('Project Cost'!$C$14-'Project Cost'!$C$5-'Project Cost'!$C$13)*Assumptions!$B$47/12*(1+Assumptions!$B$37)^(I6-1),"") -> 0 | J21: =IFERROR(('Project Cost'!$C$14-'Project Cost'!$C$5-'Project Cost'!$C$13)*Assumptions!$B$47/12*(1+Assumptions!$B$37)^(J6-1),"") -> 0 | ... BJ21: =IFERROR(('Project Cost'!$C$14-'Project Cost'!$C$5-'Project Cost'!$C$13)*Assumptions!$B$47/12*(1+Assumptions!$B$37)^(BJ6-1),"") -> 0
